<sdf version='1.6'>
  <world name='default'>
    <model name='ground_plane'>
      <static>1</static>
      <link name='link'>
        <collision name='collision'>
          <geometry>
            <plane>
              <normal>0 0 1</normal>
              <size>100 100</size>
            </plane>
          </geometry>
          <surface>
            <contact>
              <collide_bitmask>65535</collide_bitmask>
              <ode/>
            </contact>
            <friction>
              <ode>
                <mu>100</mu>
                <mu2>50</mu2>
              </ode>
              <torsional>
                <ode/>
              </torsional>
            </friction>
            <bounce/>
          </surface>
          <max_contacts>10</max_contacts>
        </collision>
        <visual name='visual'>
          <cast_shadows>0</cast_shadows>
          <geometry>
            <plane>
              <normal>0 0 1</normal>
              <size>100 100</size>
            </plane>
          </geometry>
          <material>
            <script>
              <uri>file://media/materials/scripts/gazebo.material</uri>
              <name>Gazebo/Grey</name>
            </script>
          </material>
        </visual>
        <self_collide>0</self_collide>
        <kinematic>0</kinematic>
      </link>
    </model>
    <light name='sun' type='directional'>
      <cast_shadows>1</cast_shadows>
      <pose frame=''>0 0 10 0 -0 0</pose>
      <diffuse>0.8 0.8 0.8 1</diffuse>
      <specular>0.2 0.2 0.2 1</specular>
      <attenuation>
        <range>1000</range>
        <constant>0.9</constant>
        <linear>0.01</linear>
        <quadratic>0.001</quadratic>
      </attenuation>
      <direction>-0.5 0.1 -0.9</direction>
    </light>
    <physics name='default_physics' default='0' type='ode'>
      <real_time_update_rate>0</real_time_update_rate>
      <max_step_size>0.001</max_step_size>
      <real_time_factor>1</real_time_factor>
    </physics>
    <gravity>0 0 -0.1</gravity>
    <gui fullscreen='0'>
      <camera name='user_camera'>
        <pose frame=''>4.33799 -3.40785 1.96819 -0 0.391579 2.24469</pose>
        <view_controller>ortho</view_controller>
        <projection_type>orthographic</projection_type>
      </camera>
    </gui>
    <magnetic_field>6e-06 2.3e-05 -4.2e-05</magnetic_field>
    <atmosphere type='adiabatic'/>
    <scene>
      <ambient>0.4 0.4 0.4 1</ambient>
      <background>0.7 0.7 0.7 1</background>
      <shadows>1</shadows>
    </scene>
    <spherical_coordinates>
      <surface_model>EARTH_WGS84</surface_model>
      <latitude_deg>0</latitude_deg>
      <longitude_deg>0</longitude_deg>
      <elevation>0</elevation>
      <heading_deg>0</heading_deg>
    </spherical_coordinates>
    <model name='baxter'>
      <link name='base'>
        <pose frame=''>0 0 0 0 -0 0</pose>
        <inertial>
          <pose frame=''>0 -0 3e-06 0 -0 0</pose>
          <mass>96.2011</mass>
          <inertia>
            <ixx>6.91297</ixx>
            <ixy>0.00068017</ixy>
            <ixz>0.64779</ixz>
            <iyy>7.74978</iyy>
            <iyz>0.00434511</iyz>
            <izz>5.76418</izz>
          </inertia>
        </inertial>
        <collision name='base_fixed_joint_lump__collision_head_link_1_collision'>
          <pose frame=''>0.04 -0.04 0.75 0 -0 0</pose>
          <geometry>
            <sphere>
              <radius>0.22</radius>
            </sphere>
          </geometry>
          <max_contacts>10</max_contacts>
          <surface>
            <contact>
              <ode/>
            </contact>
            <bounce/>
            <friction>
              <torsional>
                <ode/>
              </torsional>
              <ode/>
            </friction>
          </surface>
        </collision>
        <collision name='base_fixed_joint_lump__collision_head_link_2_collision_1'>
          <pose frame=''>0.04 0.04 0.75 0 -0 0</pose>
          <geometry>
            <sphere>
              <radius>0.22</radius>
            </sphere>
          </geometry>
          <max_contacts>10</max_contacts>
          <surface>
            <contact>
              <ode/>
            </contact>
            <bounce/>
            <friction>
              <torsional>
                <ode/>
              </torsional>
              <ode/>
            </friction>
          </surface>
        </collision>
        <collision name='base_fixed_joint_lump__torso_collision_2'>
          <pose frame=''>0 0 0 0 -0 0</pose>
          <geometry>
            <mesh>
              <scale>1 1 1</scale>
              <uri>/home/michaelwan/rethink_ws/src/baxter_common/baxter_description/meshes/torso/base_link_collision.DAE</uri>
            </mesh>
          </geometry>
          <surface>
            <contact>
              <ode/>
            </contact>
            <friction>
              <ode/>
              <torsional>
                <ode/>
              </torsional>
            </friction>
            <bounce/>
          </surface>
          <max_contacts>10</max_contacts>
        </collision>
        <collision name='base_fixed_joint_lump__pedestal_collision_3'>
          <pose frame=''>0 0 0 0 -0 0</pose>
          <geometry>
            <mesh>
              <scale>1 1 1</scale>
              <uri>/home/michaelwan/rethink_ws/src/baxter_common/baxter_description/meshes/base/pedestal_link_collision.DAE</uri>
            </mesh>
          </geometry>
          <max_contacts>10</max_contacts>
          <surface>
            <contact>
              <ode/>
            </contact>
            <bounce/>
            <friction>
              <torsional>
                <ode/>
              </torsional>
              <ode/>
            </friction>
          </surface>
        </collision>
        <collision name='base_fixed_joint_lump__sonar_ring_collision_4'>
          <pose frame=''>0.0947 0 0.817 0 -0 0</pose>
          <geometry>
            <sphere>
              <radius>0.001</radius>
            </sphere>
          </geometry>
          <surface>
            <contact>
              <ode/>
            </contact>
            <friction>
              <ode/>
              <torsional>
                <ode/>
              </torsional>
            </friction>
            <bounce/>
          </surface>
          <max_contacts>10</max_contacts>
        </collision>
        <visual name='base_fixed_joint_lump__collision_head_link_1_visual'>
          <pose frame=''>0.11 0 0.75 0 -0 0</pose>
          <geometry>
            <sphere>
              <radius>0.001</radius>
            </sphere>
          </geometry>
        </visual>
        <visual name='base_fixed_joint_lump__collision_head_link_2_visual_1'>
          <pose frame=''>0.11 0 0.75 0 -0 0</pose>
          <geometry>
            <sphere>
              <radius>0.001</radius>
            </sphere>
          </geometry>
        </visual>
        <visual name='base_fixed_joint_lump__torso_visual_2'>
          <pose frame=''>0 0 0 0 -0 0</pose>
          <geometry>
            <mesh>
              <scale>1 1 1</scale>
              <uri>/home/michaelwan/rethink_ws/src/baxter_common/baxter_description/meshes/torso/base_link.DAE</uri>
            </mesh>
          </geometry>
          <material>
            <script>
              <uri>__default__</uri>
              <name>__default__</name>
            </script>
          </material>
        </visual>
        <visual name='base_fixed_joint_lump__pedestal_visual_3'>
          <pose frame=''>0 0 0 0 -0 0</pose>
          <geometry>
            <mesh>
              <scale>1 1 1</scale>
              <uri>/home/michaelwan/rethink_ws/src/baxter_common/baxter_description/meshes/base/PEDESTAL.DAE</uri>
            </mesh>
          </geometry>
        </visual>
        <visual name='base_fixed_joint_lump__sonar_ring_visual_4'>
          <pose frame=''>0.06 0 0.82653 0 -0 0</pose>
          <geometry>
            <cylinder>
              <length>0.01</length>
              <radius>0.085</radius>
            </cylinder>
          </geometry>
          <material>
            <script>
              <uri>__default__</uri>
              <name>__default__</name>
            </script>
          </material>
        </visual>
        <velocity_decay/>
        <self_collide>1</self_collide>
        <gravity>1</gravity>
        <velocity_decay/>
        <sensor name='sonar' type='ray'>
          <ray>
            <scan>
              <horizontal>
                <samples>12</samples>
                <resolution>1</resolution>
                <min_angle>-3.14</min_angle>
                <max_angle>3.14</max_angle>
              </horizontal>
              <vertical>
                <samples>2</samples>
                <resolution>1</resolution>
                <min_angle>-0.001</min_angle>
                <max_angle>0</max_angle>
              </vertical>
            </scan>
            <range>
              <min>0.05</min>
              <max>50</max>
            </range>
          </ray>
          <plugin name='sonar_plugin' filename='libgazebo_ros_block_laser.so'>
            <gaussianNoise>0.00</gaussianNoise>
            <alwaysOn>true</alwaysOn>
            <updateRate>100.0</updateRate>
            <topicName>/robot/sonar/head_sonar/state</topicName>
            <frameName>sonar_ring</frameName>
            <hokuyoMinIntensity>101</hokuyoMinIntensity>
            <robotNamespace>/</robotNamespace>
          </plugin>
          <always_on>1</always_on>
          <update_rate>100</update_rate>
          <pose frame=''>0.0947 0 0.817 0 -0 0</pose>
        </sensor>
        <kinematic>0</kinematic>
      </link>
      <joint name='fixed' type='fixed'>
        <child>base</child>
        <parent>world</parent>
      </joint>
      <link name='head'>
        <pose frame=''>0.06 0 0.686 0 -0 0</pose>
        <inertial>
          <pose frame=''>0.054677 0 5e-06 0 -0 0</pose>
          <mass>0.988238</mass>
          <inertia>
            <ixx>0.00620194</ixx>
            <ixy>0.000202093</ixy>
            <ixz>0.000495898</ixz>
            <iyy>0.010977</iyy>
            <iyz>-0.00109806</iyz>
            <izz>0.00983914</izz>
          </inertia>
        </inertial>
        <collision name='head_collision'>
          <pose frame=''>0 0 0 0 -0 0</pose>
          <geometry>
            <sphere>
              <radius>0.001</radius>
            </sphere>
          </geometry>
          <max_contacts>10</max_contacts>
          <surface>
            <contact>
              <ode/>
            </contact>
            <bounce/>
            <friction>
              <torsional>
                <ode/>
              </torsional>
              <ode/>
            </friction>
          </surface>
        </collision>
        <collision name='head_fixed_joint_lump__screen_collision_1'>
          <pose frame=''>0.1227 0 0 1.75057 0 1.5708</pose>
          <geometry>
            <sphere>
              <radius>0.001</radius>
            </sphere>
          </geometry>
          <max_contacts>10</max_contacts>
          <surface>
            <contact>
              <ode/>
            </contact>
            <bounce/>
            <friction>
              <torsional>
                <ode/>
              </torsional>
              <ode/>
            </friction>
          </surface>
        </collision>
        <visual name='head_visual'>
          <pose frame=''>0 0 0.00953 0 -0 0</pose>
          <geometry>
            <mesh>
              <scale>1 1 1</scale>
              <uri>/home/michaelwan/rethink_ws/src/baxter_common/baxter_description/meshes/head/H0.DAE</uri>
            </mesh>
          </geometry>
        </visual>
        <visual name='head_fixed_joint_lump__screen_visual_1'>
          <pose frame=''>0.086855 0 -0.003172 1.5708 0.179774 0</pose>
          <geometry>
            <mesh>
              <scale>1 1 1</scale>
              <uri>/home/michaelwan/rethink_ws/src/baxter_common/baxter_description/meshes/head/H1.DAE</uri>
            </mesh>
          </geometry>
        </visual>
        <visual name='head_fixed_joint_lump__display_visual_2'>
          <pose frame=''>0.119839 0 -0.015742 2.01237 0 1.5708</pose>
          <geometry>
            <box>
              <size>0.218 0.16 0.001</size>
            </box>
          </geometry>
          <plugin name='screen_video_controller' filename='libgazebo_ros_video.so'>
            <height>600</height>
            <width>1024</width>
            <topicName>/robot/xdisplay</topicName>
            <robotNamespace>/robot</robotNamespace>
          </plugin>
          <material>
            <script>
              <uri>__default__</uri>
              <name>__default__</name>
            </script>
          </material>
        </visual>
        <velocity_decay/>
        <sensor name='head_camera' type='camera'>
          <update_rate>30</update_rate>
          <camera name='head_camera'>
            <pose frame=''>0 0.21 0 -0 -0.8 -1.5708</pose>
            <horizontal_fov>1.39626</horizontal_fov>
            <image>
              <width>800</width>
              <height>800</height>
              <format>R8G8B8</format>
            </image>
            <clip>
              <near>0.02</near>
              <far>300</far>
            </clip>
            <noise>
              <type>gaussian</type>
              <mean>0</mean>
              <stddev>0.007</stddev>
            </noise>
          </camera>
          <plugin name='camera_controller' filename='libgazebo_ros_camera.so'>
            <alwaysOn>true</alwaysOn>
            <updateRate>0.0</updateRate>
            <cameraName>head_camera</cameraName>
            <imageTopicName>image</imageTopicName>
            <cameraInfoTopicName>camera_info</cameraInfoTopicName>
            <frameName>head_camera</frameName>
            <hackBaseline>0.07</hackBaseline>
            <distortionK1>0.0</distortionK1>
            <distortionK2>0.0</distortionK2>
            <distortionK3>0.0</distortionK3>
            <distortionT1>0.0</distortionT1>
            <distortionT2>0.0</distortionT2>
            <CxPrime>0</CxPrime>
            <Cx>0.0</Cx>
            <Cy>0.0</Cy>
            <focalLength>0.0</focalLength>
            <robotNamespace>/cameras</robotNamespace>
          </plugin>
          <pose frame=''>0.12839 0 0.06368 1.75057 0 1.5708</pose>
        </sensor>
        <gravity>1</gravity>
        <velocity_decay/>
        <self_collide>0</self_collide>
        <kinematic>0</kinematic>
      </link>
      <joint name='head_pan' type='revolute'>
        <child>head</child>
        <parent>base</parent>
        <axis>
          <xyz>0 0 1</xyz>
          <limit>
            <lower>-1.3963</lower>
            <upper>1.3963</upper>
            <effort>50000</effort>
            <velocity>10000</velocity>
          </limit>
          <dynamics>
            <damping>0.7</damping>
            <friction>0</friction>
            <spring_reference>0</spring_reference>
            <spring_stiffness>0</spring_stiffness>
          </dynamics>
          <use_parent_model_frame>1</use_parent_model_frame>
        </axis>
        <physics>
          <ode>
            <implicit_spring_damper>1</implicit_spring_damper>
            <cfm_damping>1</cfm_damping>
            <limit>
              <cfm>0</cfm>
              <erp>0.2</erp>
            </limit>
          </ode>
        </physics>
      </joint>
      <link name='left_upper_shoulder'>
        <pose frame=''>0.064027 0.259027 0.129626 0 -0 0.7854</pose>
        <inertial>
          <pose frame=''>0.01783 0.00086 0.19127 0 -0 0</pose>
          <mass>5.70044</mass>
          <inertia>
            <ixx>0.047091</ixx>
            <ixy>0.000127876</ixy>
            <ixz>0.0061487</ixz>
            <iyy>0.0376698</iyy>
            <iyz>0.000780869</iyz>
            <izz>0.0359599</izz>
          </inertia>
        </inertial>
        <collision name='left_upper_shoulder_collision'>
          <pose frame=''>0 0 0.1361 0 -0 0</pose>
          <geometry>
            <cylinder>
              <length>0.2722</length>
              <radius>0.06</radius>
            </cylinder>
          </geometry>
          <max_contacts>10</max_contacts>
          <surface>
            <contact>
              <ode/>
            </contact>
            <bounce/>
            <friction>
              <torsional>
                <ode/>
              </torsional>
              <ode/>
            </friction>
          </surface>
        </collision>
        <visual name='left_upper_shoulder_visual'>
          <pose frame=''>0 0 0 0 -0 0</pose>
          <geometry>
            <mesh>
              <scale>1 1 1</scale>
              <uri>/home/michaelwan/rethink_ws/src/baxter_common/baxter_description/meshes/upper_shoulder/S0.DAE</uri>
            </mesh>
          </geometry>
        </visual>
        <self_collide>0</self_collide>
        <kinematic>0</kinematic>
      </link>
      <joint name='left_s0' type='revolute'>
        <child>left_upper_shoulder</child>
        <parent>base</parent>
        <axis>
          <xyz>0 0 1</xyz>
          <limit>
            <lower>-1.70168</lower>
            <upper>1.70168</upper>
            <effort>50</effort>
            <velocity>1.5</velocity>
          </limit>
          <dynamics>
            <damping>0.7</damping>
            <friction>0</friction>
            <spring_reference>0</spring_reference>
            <spring_stiffness>0</spring_stiffness>
          </dynamics>
          <use_parent_model_frame>1</use_parent_model_frame>
        </axis>
        <physics>
          <ode>
            <implicit_spring_damper>1</implicit_spring_damper>
            <cfm_damping>1</cfm_damping>
            <limit>
              <cfm>0</cfm>
              <erp>0.2</erp>
            </limit>
          </ode>
        </physics>
      </joint>
      <link name='left_lower_shoulder'>
        <pose frame=''>0.112818 0.307818 0.399976 -1.5708 -0 0.7854</pose>
        <inertial>
          <pose frame=''>0.068451 0.00269 -0.00529 0 -0 0</pose>
          <mass>3.22708</mass>
          <inertia>
            <ixx>0.0117521</ixx>
            <ixy>-0.000300954</ixy>
            <ixz>0.00207674</ixz>
            <iyy>0.0278861</iyy>
            <iyz>-0.000188219</iyz>
            <izz>0.0207877</izz>
          </inertia>
        </inertial>
        <collision name='left_lower_shoulder_collision'>
          <pose frame=''>0 0 0 0 -0 0</pose>
          <geometry>
            <cylinder>
              <length>0.12</length>
              <radius>0.06</radius>
            </cylinder>
          </geometry>
          <max_contacts>10</max_contacts>
          <surface>
            <contact>
              <ode/>
            </contact>
            <bounce/>
            <friction>
              <torsional>
                <ode/>
              </torsional>
              <ode/>
            </friction>
          </surface>
        </collision>
        <collision name='left_lower_shoulder_fixed_joint_lump__left_upper_elbow_visual_collision_1'>
          <pose frame=''>0.2435 -0 0 1.5708 -0 1.5708</pose>
          <geometry>
            <cylinder>
              <length>0.273</length>
              <radius>0.06</radius>
            </cylinder>
          </geometry>
          <max_contacts>10</max_contacts>
          <surface>
            <contact>
              <ode/>
            </contact>
            <bounce/>
            <friction>
              <torsional>
                <ode/>
              </torsional>
              <ode/>
            </friction>
          </surface>
        </collision>
        <visual name='left_lower_shoulder_visual'>
          <pose frame=''>0 0 0 0 -0 0</pose>
          <geometry>
            <mesh>
              <scale>1 1 1</scale>
              <uri>/home/michaelwan/rethink_ws/src/baxter_common/baxter_description/meshes/lower_shoulder/S1.DAE</uri>
            </mesh>
          </geometry>
        </visual>
        <self_collide>0</self_collide>
        <kinematic>0</kinematic>
      </link>
      <joint name='left_s1' type='revolute'>
        <child>left_lower_shoulder</child>
        <parent>left_upper_shoulder</parent>
        <axis>
          <xyz>-0.707108 0.707105 0</xyz>
          <limit>
            <lower>-2.147</lower>
            <upper>1.047</upper>
            <effort>50</effort>
            <velocity>1.5</velocity>
          </limit>
          <dynamics>
            <damping>0.7</damping>
            <friction>0</friction>
            <spring_reference>0</spring_reference>
            <spring_stiffness>0</spring_stiffness>
          </dynamics>
          <use_parent_model_frame>1</use_parent_model_frame>
        </axis>
        <physics>
          <ode>
            <implicit_spring_damper>1</implicit_spring_damper>
            <cfm_damping>1</cfm_damping>
            <limit>
              <cfm>0</cfm>
              <erp>0.2</erp>
            </limit>
          </ode>
        </physics>
      </joint>
      <link name='left_upper_elbow'>
        <pose frame=''>0.184942 0.379943 0.399976 2.35619 1.57079 3.14159</pose>
        <inertial>
          <pose frame=''>-0.00276 0.00132 0.18086 0 -0 0</pose>
          <mass>4.31272</mass>
          <inertia>
            <ixx>0.0266173</ixx>
            <ixy>0.000292706</ixy>
            <ixz>0.0039219</ixz>
            <iyy>0.0284436</iyy>
            <iyz>0.00108389</iyz>
            <izz>0.0124801</izz>
          </inertia>
        </inertial>
        <collision name='left_upper_elbow_collision'>
          <pose frame=''>0 0 -0.0535 0 -0 0</pose>
          <geometry>
            <cylinder>
              <length>0.107</length>
              <radius>0.06</radius>
            </cylinder>
          </geometry>
          <max_contacts>10</max_contacts>
          <surface>
            <contact>
              <ode/>
            </contact>
            <bounce/>
            <friction>
              <torsional>
                <ode/>
              </torsional>
              <ode/>
            </friction>
          </surface>
        </collision>
        <visual name='left_upper_elbow_visual'>
          <pose frame=''>0 0 0 0 -0 0</pose>
          <geometry>
            <mesh>
              <scale>1 1 1</scale>
              <uri>/home/michaelwan/rethink_ws/src/baxter_common/baxter_description/meshes/upper_elbow/E0.DAE</uri>
            </mesh>
          </geometry>
        </visual>
        <self_collide>0</self_collide>
        <kinematic>0</kinematic>
      </link>
      <joint name='left_e0' type='revolute'>
        <child>left_upper_elbow</child>
        <parent>left_lower_shoulder</parent>
        <axis>
          <xyz>0.707105 0.707108 0</xyz>
          <limit>
            <lower>-3.05418</lower>
            <upper>3.05418</upper>
            <effort>50</effort>
            <velocity>1.5</velocity>
          </limit>
          <dynamics>
            <damping>0.7</damping>
            <friction>0</friction>
            <spring_reference>0</spring_reference>
            <spring_stiffness>0</spring_stiffness>
          </dynamics>
          <use_parent_model_frame>1</use_parent_model_frame>
        </axis>
        <physics>
          <ode>
            <implicit_spring_damper>1</implicit_spring_damper>
            <cfm_damping>1</cfm_damping>
            <limit>
              <cfm>0</cfm>
              <erp>0.2</erp>
            </limit>
          </ode>
        </physics>
      </joint>
      <link name='left_lower_elbow'>
        <pose frame=''>0.370501 0.565502 0.330976 -1.5708 -0 0.7854</pose>
        <inertial>
          <pose frame=''>0.026113 0.00159 -0.01117 0 -0 0</pose>
          <mass>2.07216</mass>
          <inertia>
            <ixx>0.00711585</ixx>
            <ixy>0.000360372</ixy>
            <ixz>0.00074588</ixz>
            <iyy>0.0131827</iyy>
            <iyz>-0.000196632</iyz>
            <izz>0.00926891</izz>
          </inertia>
        </inertial>
        <collision name='left_lower_elbow_collision'>
          <pose frame=''>0 0 0 0 -0 0</pose>
          <geometry>
            <cylinder>
              <length>0.1</length>
              <radius>0.06</radius>
            </cylinder>
          </geometry>
          <max_contacts>10</max_contacts>
          <surface>
            <contact>
              <ode/>
            </contact>
            <bounce/>
            <friction>
              <torsional>
                <ode/>
              </torsional>
              <ode/>
            </friction>
          </surface>
        </collision>
        <collision name='left_lower_elbow_fixed_joint_lump__left_upper_forearm_visual_collision_1'>
          <pose frame=''>0.224 -0 0 1.5708 -0 1.5708</pose>
          <geometry>
            <cylinder>
              <length>0.272</length>
              <radius>0.06</radius>
            </cylinder>
          </geometry>
          <max_contacts>10</max_contacts>
          <surface>
            <contact>
              <ode/>
            </contact>
            <bounce/>
            <friction>
              <torsional>
                <ode/>
              </torsional>
              <ode/>
            </friction>
          </surface>
        </collision>
        <visual name='left_lower_elbow_visual'>
          <pose frame=''>0 0 0 0 -0 0</pose>
          <geometry>
            <mesh>
              <scale>1 1 1</scale>
              <uri>/home/michaelwan/rethink_ws/src/baxter_common/baxter_description/meshes/lower_elbow/E1.DAE</uri>
            </mesh>
          </geometry>
        </visual>
        <self_collide>0</self_collide>
        <kinematic>0</kinematic>
      </link>
      <joint name='left_e1' type='revolute'>
        <child>left_lower_elbow</child>
        <parent>left_upper_elbow</parent>
        <axis>
          <xyz>-0.707108 0.707105 0</xyz>
          <limit>
            <lower>-0.05</lower>
            <upper>2.618</upper>
            <effort>50</effort>
            <velocity>1.5</velocity>
          </limit>
          <dynamics>
            <damping>0.7</damping>
            <friction>0</friction>
            <spring_reference>0</spring_reference>
            <spring_stiffness>0</spring_stiffness>
          </dynamics>
          <use_parent_model_frame>1</use_parent_model_frame>
        </axis>
        <physics>
          <ode>
            <implicit_spring_damper>1</implicit_spring_damper>
            <cfm_damping>1</cfm_damping>
            <limit>
              <cfm>0</cfm>
              <erp>0.2</erp>
            </limit>
          </ode>
        </physics>
      </joint>
      <link name='left_upper_forearm'>
        <pose frame=''>0.44375 0.638751 0.330976 2.35619 1.57079 3.14159</pose>
        <inertial>
          <pose frame=''>-0.001682 0.0046 0.139519 0 -0 0</pose>
          <mass>2.24675</mass>
          <inertia>
            <ixx>0.0166775</ixx>
            <ixy>0.000184012</ixy>
            <ixz>0.000186469</ixz>
            <iyy>0.0167549</iyy>
            <iyz>-0.000647332</iyz>
            <izz>0.00374662</izz>
          </inertia>
        </inertial>
        <collision name='left_upper_forearm_collision'>
          <pose frame=''>0 0 -0.044 0 -0 0</pose>
          <geometry>
            <cylinder>
              <length>0.088</length>
              <radius>0.06</radius>
            </cylinder>
          </geometry>
          <max_contacts>10</max_contacts>
          <surface>
            <contact>
              <ode/>
            </contact>
            <bounce/>
            <friction>
              <torsional>
                <ode/>
              </torsional>
              <ode/>
            </friction>
          </surface>
        </collision>
        <visual name='left_upper_forearm_visual'>
          <pose frame=''>0 0 0 0 -0 0</pose>
          <geometry>
            <mesh>
              <scale>1 1 1</scale>
              <uri>/home/michaelwan/rethink_ws/src/baxter_common/baxter_description/meshes/upper_forearm/W0.DAE</uri>
            </mesh>
          </geometry>
        </visual>
        <self_collide>0</self_collide>
        <kinematic>0</kinematic>
      </link>
      <joint name='left_w0' type='revolute'>
        <child>left_upper_forearm</child>
        <parent>left_lower_elbow</parent>
        <axis>
          <xyz>0.707105 0.707108 0</xyz>
          <limit>
            <lower>-3.059</lower>
            <upper>3.059</upper>
            <effort>15</effort>
            <velocity>4</velocity>
          </limit>
          <dynamics>
            <damping>0.7</damping>
            <friction>0</friction>
            <spring_reference>0</spring_reference>
            <spring_stiffness>0</spring_stiffness>
          </dynamics>
          <use_parent_model_frame>1</use_parent_model_frame>
        </axis>
        <physics>
          <ode>
            <implicit_spring_damper>1</implicit_spring_damper>
            <cfm_damping>1</cfm_damping>
            <limit>
              <cfm>0</cfm>
              <erp>0.2</erp>
            </limit>
          </ode>
        </physics>
      </joint>
      <link name='left_lower_forearm'>
        <pose frame=''>0.635163 0.830166 0.320976 -1.5708 -0 0.7854</pose>
        <inertial>
          <pose frame=''>0.06041 0.00697 0.006 0 -0 0</pose>
          <mass>1.60979</mass>
          <inertia>
            <ixx>0.00387607</ixx>
            <ixy>-0.000443848</ixy>
            <ixz>-0.00021115</ixz>
            <iyy>0.00700538</iyy>
            <iyz>0.000153481</iyz>
            <izz>0.00552755</izz>
          </inertia>
        </inertial>
        <collision name='left_lower_forearm_collision'>
          <pose frame=''>0 0 0 0 -0 0</pose>
          <geometry>
            <cylinder>
              <length>0.1</length>
              <radius>0.06</radius>
            </cylinder>
          </geometry>
          <max_contacts>10</max_contacts>
          <surface>
            <contact>
              <ode/>
            </contact>
            <bounce/>
            <friction>
              <torsional>
                <ode/>
              </torsional>
              <ode/>
            </friction>
          </surface>
        </collision>
        <visual name='left_lower_forearm_visual'>
          <pose frame=''>0 0 0 0 -0 0</pose>
          <geometry>
            <mesh>
              <scale>1 1 1</scale>
              <uri>/home/michaelwan/rethink_ws/src/baxter_common/baxter_description/meshes/lower_forearm/W1.DAE</uri>
            </mesh>
          </geometry>
        </visual>
        <self_collide>0</self_collide>
        <kinematic>0</kinematic>
      </link>
      <joint name='left_w1' type='revolute'>
        <child>left_lower_forearm</child>
        <parent>left_upper_forearm</parent>
        <axis>
          <xyz>-0.707108 0.707105 0</xyz>
          <limit>
            <lower>-1.5708</lower>
            <upper>2.094</upper>
            <effort>15</effort>
            <velocity>4</velocity>
          </limit>
          <dynamics>
            <damping>0.7</damping>
            <friction>0</friction>
            <spring_reference>0</spring_reference>
            <spring_stiffness>0</spring_stiffness>
          </dynamics>
          <use_parent_model_frame>1</use_parent_model_frame>
        </axis>
        <physics>
          <ode>
            <implicit_spring_damper>1</implicit_spring_damper>
            <cfm_damping>1</cfm_damping>
            <limit>
              <cfm>0</cfm>
              <erp>0.2</erp>
            </limit>
          </ode>
        </physics>
      </joint>
      <link name='left_wrist'>
        <pose frame=''>0.71717 0.912173 0.320976 2.35619 1.57079 3.14159</pose>
        <inertial>
          <pose frame=''>0.003318 0.000616 0.079435 0 -0 0</pose>
          <mass>0.84268</mass>
          <inertia>
            <ixx>0.00285059</ixx>
            <ixy>7.17373e-06</ixy>
            <ixz>2.52032e-05</ixz>
            <iyy>0.00291735</iyy>
            <iyz>2.17353e-05</iyz>
            <izz>0.000560608</izz>
          </inertia>
        </inertial>
        <collision name='left_wrist_collision'>
          <pose frame=''>0 0 0 0 -0 0</pose>
          <geometry>
            <cylinder>
              <length>0.165</length>
              <radius>0.06</radius>
            </cylinder>
          </geometry>
          <max_contacts>10</max_contacts>
          <surface>
            <contact>
              <ode/>
            </contact>
            <bounce/>
            <friction>
              <torsional>
                <ode/>
              </torsional>
              <ode/>
            </friction>
          </surface>
        </collision>
        <collision name='left_wrist_fixed_joint_lump__left_hand_collision_1'>
          <pose frame=''>0 0 0.09035 0 -0 0</pose>
          <geometry>
            <cylinder>
              <length>0.0464</length>
              <radius>0.04</radius>
            </cylinder>
          </geometry>
          <max_contacts>10</max_contacts>
          <surface>
            <contact>
              <ode/>
            </contact>
            <bounce/>
            <friction>
              <torsional>
                <ode/>
              </torsional>
              <ode/>
            </friction>
          </surface>
        </collision>
        <collision name='left_wrist_fixed_joint_lump__left_gripper_base_collision_2'>
          <pose frame=''>0 0 0.13855 1.5708 -0 3.14159</pose>
          <geometry>
            <cylinder>
              <length>0.1</length>
              <radius>0.029</radius>
            </cylinder>
          </geometry>
          <max_contacts>10</max_contacts>
          <surface>
            <contact>
              <ode/>
            </contact>
            <bounce/>
            <friction>
              <torsional>
                <ode/>
              </torsional>
              <ode/>
            </friction>
          </surface>
        </collision>
        <visual name='left_wrist_visual'>
          <pose frame=''>0 0 0 0 -0 0</pose>
          <geometry>
            <mesh>
              <scale>1 1 1</scale>
              <uri>/home/michaelwan/rethink_ws/src/baxter_common/baxter_description/meshes/wrist/W2.DAE</uri>
            </mesh>
          </geometry>
        </visual>
        <visual name='left_wrist_fixed_joint_lump__left_gripper_base_visual_1'>
          <pose frame=''>0 0 0.13855 1.5708 -0 3.14159</pose>
          <geometry>
            <mesh>
              <scale>1 1 1</scale>
              <uri>/home/michaelwan/rethink_ws/src/baxter_common/rethink_ee_description/meshes/electric_gripper/electric_gripper_base.DAE</uri>
            </mesh>
          </geometry>
        </visual>
        <visual name='left_wrist_fixed_joint_lump__left_hand_accelerometer_visual_2'>
          <pose frame=''>0.00198 0.000133 0.09895 0 -0 0</pose>
          <geometry>
            <box>
              <size>0.01 0.01 0.01</size>
            </box>
          </geometry>
        </visual>
        <visual name='left_wrist_fixed_joint_lump__left_hand_camera_visual_3'>
          <pose frame=''>0.03825 0.012 0.128905 0 0 -1.5708</pose>
          <geometry>
            <cylinder>
              <length>0.01</length>
              <radius>0.02</radius>
            </cylinder>
          </geometry>
          <material>
            <script>
              <uri>__default__</uri>
              <name>__default__</name>
            </script>
          </material>
        </visual>
        <visual name='left_wrist_fixed_joint_lump__left_hand_range_visual_4'>
          <pose frame=''>0.032 -0.020245 0.14235 -3.14158 -1.57079 1.57078</pose>
          <geometry>
            <box>
              <size>0.005 0.02 0.005</size>
            </box>
          </geometry>
          <material>
            <script>
              <uri>__default__</uri>
              <name>__default__</name>
            </script>
          </material>
        </visual>
        <velocity_decay/>
        <sensor name='left_hand_camera' type='camera'>
          <update_rate>30</update_rate>
          <camera name='left_hand_camera'>
            <pose frame=''>0 0 0 -1.57079 -1.57079 3.14159</pose>
            <horizontal_fov>1.39626</horizontal_fov>
            <image>
              <width>800</width>
              <height>800</height>
              <format>R8G8B8</format>
            </image>
            <clip>
              <near>0.02</near>
              <far>300</far>
            </clip>
            <noise>
              <type>gaussian</type>
              <mean>0</mean>
              <stddev>0.007</stddev>
            </noise>
          </camera>
          <plugin name='camera_controller' filename='libgazebo_ros_camera.so'>
            <alwaysOn>true</alwaysOn>
            <updateRate>0.0</updateRate>
            <cameraName>left_hand_camera</cameraName>
            <imageTopicName>image</imageTopicName>
            <cameraInfoTopicName>camera_info</cameraInfoTopicName>
            <frameName>left_hand_camera</frameName>
            <hackBaseline>0.07</hackBaseline>
            <distortionK1>0.0</distortionK1>
            <distortionK2>0.0</distortionK2>
            <distortionK3>0.0</distortionK3>
            <distortionT1>0.0</distortionT1>
            <distortionT2>0.0</distortionT2>
            <CxPrime>0</CxPrime>
            <Cx>0.0</Cx>
            <Cy>0.0</Cy>
            <focalLength>0.0</focalLength>
            <robotNamespace>/cameras</robotNamespace>
          </plugin>
          <pose frame=''>0.03825 0.012 0.128905 0 0 -1.5708</pose>
        </sensor>
        <gravity>0</gravity>
        <velocity_decay/>
        <sensor name='ir_left' type='ray'>
          <ray>
            <scan>
              <horizontal>
                <samples>1</samples>
                <resolution>1</resolution>
                <min_angle>-0.5</min_angle>
                <max_angle>0.5</max_angle>
              </horizontal>
              <vertical>
                <samples>1</samples>
                <min_angle>0</min_angle>
                <max_angle>0</max_angle>
              </vertical>
            </scan>
            <range>
              <min>0.004</min>
              <max>0.4</max>
            </range>
          </ray>
          <plugin name='plugin_4' filename='libgazebo_ros_laser.so'>
            <gaussianNoise>0.005</gaussianNoise>
            <alwaysOn>true</alwaysOn>
            <updateRate>100</updateRate>
            <topicName>/sim/laserscan/left_hand_range/state</topicName>
            <frameName>left_hand_range</frameName>
            <robotNamespace>/</robotNamespace>
          </plugin>
          <always_on>1</always_on>
          <update_rate>100</update_rate>
          <pose frame=''>0.032 -0.020245 0.14235 -3.14158 -1.57079 1.57078</pose>
        </sensor>
        <self_collide>0</self_collide>
        <kinematic>0</kinematic>
      </link>
      <joint name='left_w2' type='revolute'>
        <child>left_wrist</child>
        <parent>left_lower_forearm</parent>
        <axis>
          <xyz>0.707105 0.707108 0</xyz>
          <limit>
            <lower>-3.059</lower>
            <upper>3.059</upper>
            <effort>15</effort>
            <velocity>4</velocity>
          </limit>
          <dynamics>
            <damping>0.7</damping>
            <friction>0</friction>
            <spring_reference>0</spring_reference>
            <spring_stiffness>0</spring_stiffness>
          </dynamics>
          <use_parent_model_frame>1</use_parent_model_frame>
        </axis>
        <physics>
          <ode>
            <implicit_spring_damper>1</implicit_spring_damper>
            <cfm_damping>1</cfm_damping>
            <limit>
              <cfm>0</cfm>
              <erp>0.2</erp>
            </limit>
          </ode>
        </physics>
      </joint>
      <link name='l_gripper_l_finger'>
        <pose frame=''>0.830342 1.02322 0.320976 2.35619 1.57079 3.14159</pose>
        <inertial>
          <pose frame=''>0 0.00575 0.037567 0 -0 3.14159</pose>
          <mass>0.03</mass>
          <inertia>
            <ixx>0.0200867</ixx>
            <ixy>4.0989e-19</ixy>
            <ixz>-2.67795e-18</ixz>
            <iyy>0.0200847</iyy>
            <iyz>1.29605e-05</iyz>
            <izz>0.020002</izz>
          </inertia>
        </inertial>
        <collision name='l_gripper_l_finger_collision'>
          <pose frame=''>0 0.01725 0.0615 0 -0 3.14159</pose>
          <geometry>
            <box>
              <size>0.01 0.0135 0.1127</size>
            </box>
          </geometry>
          <surface>
            <contact>
              <ode>
                <kp>100000</kp>
                <kd>1</kd>
              </ode>
            </contact>
            <friction>
              <ode>
                <mu>1000</mu>
                <mu2>1000</mu2>
                <fdir1>0 0 1</fdir1>
              </ode>
              <torsional>
                <ode/>
              </torsional>
            </friction>
            <bounce/>
          </surface>
          <max_contacts>10</max_contacts>
        </collision>
        <collision name='l_gripper_l_finger_collision_1'>
          <pose frame=''>-0.005 -0.003 0.0083 0 -0 3.14159</pose>
          <geometry>
            <box>
              <size>0.01 0.05 0.017</size>
            </box>
          </geometry>
          <surface>
            <contact>
              <ode>
                <kp>100000</kp>
                <kd>1</kd>
              </ode>
            </contact>
            <friction>
              <ode>
                <mu>1000</mu>
                <mu2>1000</mu2>
                <fdir1>0 0 1</fdir1>
              </ode>
              <torsional>
                <ode/>
              </torsional>
            </friction>
            <bounce/>
          </surface>
          <max_contacts>10</max_contacts>
        </collision>
        <collision name='l_gripper_l_finger_tip_collision_2'>
          <pose frame=''>0 0.01275 0.0977 0 -0 -3.14159</pose>
          <geometry>
            <box>
              <size>0.042 0.0065 0.037</size>
            </box>
          </geometry>
          <surface>
            <contact>
              <ode>
                <kp>100000</kp>
                <kd>1</kd>
              </ode>
            </contact>
            <friction>
              <ode>
                <mu>1000</mu>
                <mu2>1000</mu2>
                <fdir1>0 0 1</fdir1>
              </ode>
              <torsional>
                <ode/>
              </torsional>
            </friction>
            <bounce/>
          </surface>
          <max_contacts>10</max_contacts>
        </collision>
        <visual name='l_gripper_l_finger_visual'>
          <pose frame=''>0 0 0 0 -0 3.14159</pose>
          <geometry>
            <mesh>
              <scale>1 1 1</scale>
              <uri>/home/michaelwan/rethink_ws/src/baxter_common/rethink_ee_description/meshes/electric_gripper/fingers/extended_narrow.DAE</uri>
            </mesh>
          </geometry>
          <material>
            <script>
              <uri>__default__</uri>
              <name>__default__</name>
            </script>
          </material>
        </visual>
        <visual name='l_gripper_l_finger_tip_visual_1'>
          <pose frame=''>0 0.01725 0.1127 0 -0 -3.14159</pose>
          <geometry>
            <mesh>
              <scale>1 1 1</scale>
              <uri>/home/michaelwan/rethink_ws/src/baxter_common/rethink_ee_description/meshes/electric_gripper/fingers/paddle_tip.DAE</uri>
            </mesh>
          </geometry>
          <material>
            <script>
              <uri>__default__</uri>
              <name>__default__</name>
            </script>
          </material>
        </visual>
        <gravity>1</gravity>
        <velocity_decay/>
        <self_collide>0</self_collide>
        <kinematic>0</kinematic>
      </link>
      <joint name='l_gripper_l_finger_joint' type='prismatic'>
        <child>l_gripper_l_finger</child>
        <parent>left_wrist</parent>
        <axis>
          <xyz>-0.707108 0.707105 0</xyz>
          <limit>
            <lower>0</lower>
            <upper>0.020833</upper>
            <effort>20</effort>
            <velocity>5</velocity>
          </limit>
          <dynamics>
            <damping>0.7</damping>
            <friction>0</friction>
            <spring_reference>0</spring_reference>
            <spring_stiffness>0</spring_stiffness>
          </dynamics>
          <use_parent_model_frame>1</use_parent_model_frame>
        </axis>
        <physics>
          <ode>
            <implicit_spring_damper>1</implicit_spring_damper>
            <cfm_damping>1</cfm_damping>
            <limit>
              <cfm>0</cfm>
              <erp>0.2</erp>
            </limit>
          </ode>
        </physics>
      </joint>
      <link name='l_gripper_r_finger'>
        <pose frame=''>0.828221 1.02535 0.320976 2.35619 1.57079 3.14159</pose>
        <inertial>
          <pose frame=''>0 -0.00575 0.037567 0 -0 0</pose>
          <mass>0.03</mass>
          <inertia>
            <ixx>0.0200867</ixx>
            <ixy>0</ixy>
            <ixz>0</ixz>
            <iyy>0.0200847</iyy>
            <iyz>1.29605e-05</iyz>
            <izz>0.020002</izz>
          </inertia>
        </inertial>
        <collision name='l_gripper_r_finger_collision'>
          <pose frame=''>0 -0.01725 0.0615 0 -0 0</pose>
          <geometry>
            <box>
              <size>0.01 0.0135 0.1127</size>
            </box>
          </geometry>
          <surface>
            <contact>
              <ode>
                <kp>100000</kp>
                <kd>1</kd>
              </ode>
            </contact>
            <friction>
              <ode>
                <mu>1000</mu>
                <mu2>1000</mu2>
                <fdir1>0 0 1</fdir1>
              </ode>
              <torsional>
                <ode/>
              </torsional>
            </friction>
            <bounce/>
          </surface>
          <max_contacts>10</max_contacts>
        </collision>
        <collision name='l_gripper_r_finger_collision_1'>
          <pose frame=''>0.005 0.003 0.0083 0 -0 0</pose>
          <geometry>
            <box>
              <size>0.01 0.05 0.017</size>
            </box>
          </geometry>
          <surface>
            <contact>
              <ode>
                <kp>100000</kp>
                <kd>1</kd>
              </ode>
            </contact>
            <friction>
              <ode>
                <mu>1000</mu>
                <mu2>1000</mu2>
                <fdir1>0 0 1</fdir1>
              </ode>
              <torsional>
                <ode/>
              </torsional>
            </friction>
            <bounce/>
          </surface>
          <max_contacts>10</max_contacts>
        </collision>
        <collision name='l_gripper_r_finger_tip_collision_2'>
          <pose frame=''>0 -0.01275 0.0977 0 -0 0</pose>
          <geometry>
            <box>
              <size>0.042 0.0065 0.037</size>
            </box>
          </geometry>
          <surface>
            <contact>
              <ode>
                <kp>100000</kp>
                <kd>1</kd>
              </ode>
            </contact>
            <friction>
              <ode>
                <mu>1000</mu>
                <mu2>1000</mu2>
                <fdir1>0 0 1</fdir1>
              </ode>
              <torsional>
                <ode/>
              </torsional>
            </friction>
            <bounce/>
          </surface>
          <max_contacts>10</max_contacts>
        </collision>
        <visual name='l_gripper_r_finger_visual'>
          <pose frame=''>0 0 0 0 -0 0</pose>
          <geometry>
            <mesh>
              <scale>1 1 1</scale>
              <uri>/home/michaelwan/rethink_ws/src/baxter_common/rethink_ee_description/meshes/electric_gripper/fingers/extended_narrow.DAE</uri>
            </mesh>
          </geometry>
          <material>
            <script>
              <uri>__default__</uri>
              <name>__default__</name>
            </script>
          </material>
        </visual>
        <visual name='l_gripper_r_finger_tip_visual_1'>
          <pose frame=''>0 -0.01725 0.1127 0 -0 0</pose>
          <geometry>
            <mesh>
              <scale>1 1 1</scale>
              <uri>/home/michaelwan/rethink_ws/src/baxter_common/rethink_ee_description/meshes/electric_gripper/fingers/paddle_tip.DAE</uri>
            </mesh>
          </geometry>
          <material>
            <script>
              <uri>__default__</uri>
              <name>__default__</name>
            </script>
          </material>
        </visual>
        <gravity>1</gravity>
        <velocity_decay/>
        <self_collide>0</self_collide>
        <kinematic>0</kinematic>
      </link>
      <joint name='l_gripper_r_finger_joint' type='prismatic'>
        <child>l_gripper_r_finger</child>
        <parent>left_wrist</parent>
        <axis>
          <xyz>-0.707108 0.707105 0</xyz>
          <limit>
            <lower>-0.020833</lower>
            <upper>0</upper>
            <effort>20</effort>
            <velocity>5</velocity>
          </limit>
          <dynamics>
            <damping>0.7</damping>
            <friction>0</friction>
            <spring_reference>0</spring_reference>
            <spring_stiffness>0</spring_stiffness>
          </dynamics>
          <use_parent_model_frame>1</use_parent_model_frame>
        </axis>
        <physics>
          <ode>
            <implicit_spring_damper>1</implicit_spring_damper>
            <cfm_damping>1</cfm_damping>
            <limit>
              <cfm>0</cfm>
              <erp>0.2</erp>
            </limit>
          </ode>
        </physics>
      </joint>
      <link name='right_upper_shoulder'>
        <pose frame=''>0.064027 -0.259027 0.129626 0 0 -0.7854</pose>
        <inertial>
          <pose frame=''>0.01783 0.00086 0.19127 0 -0 0</pose>
          <mass>5.70044</mass>
          <inertia>
            <ixx>0.047091</ixx>
            <ixy>0.000127876</ixy>
            <ixz>0.0061487</ixz>
            <iyy>0.0376698</iyy>
            <iyz>0.000780869</iyz>
            <izz>0.0359599</izz>
          </inertia>
        </inertial>
        <collision name='right_upper_shoulder_collision'>
          <pose frame=''>0 0 0.1361 0 -0 0</pose>
          <geometry>
            <cylinder>
              <length>0.2722</length>
              <radius>0.06</radius>
            </cylinder>
          </geometry>
          <max_contacts>10</max_contacts>
          <surface>
            <contact>
              <ode/>
            </contact>
            <bounce/>
            <friction>
              <torsional>
                <ode/>
              </torsional>
              <ode/>
            </friction>
          </surface>
        </collision>
        <visual name='right_upper_shoulder_visual'>
          <pose frame=''>0 0 0 0 -0 0</pose>
          <geometry>
            <mesh>
              <scale>1 1 1</scale>
              <uri>/home/michaelwan/rethink_ws/src/baxter_common/baxter_description/meshes/upper_shoulder/S0.DAE</uri>
            </mesh>
          </geometry>
        </visual>
        <self_collide>0</self_collide>
        <kinematic>0</kinematic>
      </link>
      <joint name='right_s0' type='revolute'>
        <child>right_upper_shoulder</child>
        <parent>base</parent>
        <axis>
          <xyz>0 0 1</xyz>
          <limit>
            <lower>-1.70168</lower>
            <upper>1.70168</upper>
            <effort>50</effort>
            <velocity>1.5</velocity>
          </limit>
          <dynamics>
            <damping>0.7</damping>
            <friction>0</friction>
            <spring_reference>0</spring_reference>
            <spring_stiffness>0</spring_stiffness>
          </dynamics>
          <use_parent_model_frame>1</use_parent_model_frame>
        </axis>
        <physics>
          <ode>
            <implicit_spring_damper>1</implicit_spring_damper>
            <cfm_damping>1</cfm_damping>
            <limit>
              <cfm>0</cfm>
              <erp>0.2</erp>
            </limit>
          </ode>
        </physics>
      </joint>
      <link name='right_lower_shoulder'>
        <pose frame=''>0.112818 -0.307818 0.399976 -1.5708 -0 -0.7854</pose>
        <inertial>
          <pose frame=''>0.068451 0.00269 -0.00529 0 -0 0</pose>
          <mass>3.22708</mass>
          <inertia>
            <ixx>0.0117521</ixx>
            <ixy>-0.000300954</ixy>
            <ixz>0.00207674</ixz>
            <iyy>0.0278861</iyy>
            <iyz>-0.000188219</iyz>
            <izz>0.0207877</izz>
          </inertia>
        </inertial>
        <collision name='right_lower_shoulder_collision'>
          <pose frame=''>0 0 0 0 -0 0</pose>
          <geometry>
            <cylinder>
              <length>0.12</length>
              <radius>0.06</radius>
            </cylinder>
          </geometry>
          <max_contacts>10</max_contacts>
          <surface>
            <contact>
              <ode/>
            </contact>
            <bounce/>
            <friction>
              <torsional>
                <ode/>
              </torsional>
              <ode/>
            </friction>
          </surface>
        </collision>
        <collision name='right_lower_shoulder_fixed_joint_lump__right_upper_elbow_visual_collision_1'>
          <pose frame=''>0.2435 -0 0 1.5708 -0 1.5708</pose>
          <geometry>
            <cylinder>
              <length>0.273</length>
              <radius>0.06</radius>
            </cylinder>
          </geometry>
          <max_contacts>10</max_contacts>
          <surface>
            <contact>
              <ode/>
            </contact>
            <bounce/>
            <friction>
              <torsional>
                <ode/>
              </torsional>
              <ode/>
            </friction>
          </surface>
        </collision>
        <visual name='right_lower_shoulder_visual'>
          <pose frame=''>0 0 0 0 -0 0</pose>
          <geometry>
            <mesh>
              <scale>1 1 1</scale>
              <uri>/home/michaelwan/rethink_ws/src/baxter_common/baxter_description/meshes/lower_shoulder/S1.DAE</uri>
            </mesh>
          </geometry>
        </visual>
        <self_collide>0</self_collide>
        <kinematic>0</kinematic>
      </link>
      <joint name='right_s1' type='revolute'>
        <child>right_lower_shoulder</child>
        <parent>right_upper_shoulder</parent>
        <axis>
          <xyz>0.707108 0.707105 0</xyz>
          <limit>
            <lower>-2.147</lower>
            <upper>1.047</upper>
            <effort>50</effort>
            <velocity>1.5</velocity>
          </limit>
          <dynamics>
            <damping>0.7</damping>
            <friction>0</friction>
            <spring_reference>0</spring_reference>
            <spring_stiffness>0</spring_stiffness>
          </dynamics>
          <use_parent_model_frame>1</use_parent_model_frame>
        </axis>
        <physics>
          <ode>
            <implicit_spring_damper>1</implicit_spring_damper>
            <cfm_damping>1</cfm_damping>
            <limit>
              <cfm>0</cfm>
              <erp>0.2</erp>
            </limit>
          </ode>
        </physics>
      </joint>
      <link name='right_upper_elbow'>
        <pose frame=''>0.184942 -0.379943 0.399976 -2.35619 1.57079 3.14159</pose>
        <inertial>
          <pose frame=''>-0.00276 0.00132 0.18086 0 -0 0</pose>
          <mass>4.31272</mass>
          <inertia>
            <ixx>0.0266173</ixx>
            <ixy>0.000292706</ixy>
            <ixz>0.0039219</ixz>
            <iyy>0.0284436</iyy>
            <iyz>0.00108389</iyz>
            <izz>0.0124801</izz>
          </inertia>
        </inertial>
        <collision name='right_upper_elbow_collision'>
          <pose frame=''>0 0 -0.0535 0 -0 0</pose>
          <geometry>
            <cylinder>
              <length>0.107</length>
              <radius>0.06</radius>
            </cylinder>
          </geometry>
          <max_contacts>10</max_contacts>
          <surface>
            <contact>
              <ode/>
            </contact>
            <bounce/>
            <friction>
              <torsional>
                <ode/>
              </torsional>
              <ode/>
            </friction>
          </surface>
        </collision>
        <visual name='right_upper_elbow_visual'>
          <pose frame=''>0 0 0 0 -0 0</pose>
          <geometry>
            <mesh>
              <scale>1 1 1</scale>
              <uri>/home/michaelwan/rethink_ws/src/baxter_common/baxter_description/meshes/upper_elbow/E0.DAE</uri>
            </mesh>
          </geometry>
        </visual>
        <self_collide>0</self_collide>
        <kinematic>0</kinematic>
      </link>
      <joint name='right_e0' type='revolute'>
        <child>right_upper_elbow</child>
        <parent>right_lower_shoulder</parent>
        <axis>
          <xyz>0.707105 -0.707108 0</xyz>
          <limit>
            <lower>-3.05418</lower>
            <upper>3.05418</upper>
            <effort>50</effort>
            <velocity>1.5</velocity>
          </limit>
          <dynamics>
            <damping>0.7</damping>
            <friction>0</friction>
            <spring_reference>0</spring_reference>
            <spring_stiffness>0</spring_stiffness>
          </dynamics>
          <use_parent_model_frame>1</use_parent_model_frame>
        </axis>
        <physics>
          <ode>
            <implicit_spring_damper>1</implicit_spring_damper>
            <cfm_damping>1</cfm_damping>
            <limit>
              <cfm>0</cfm>
              <erp>0.2</erp>
            </limit>
          </ode>
        </physics>
      </joint>
      <link name='right_lower_elbow'>
        <pose frame=''>0.370501 -0.565502 0.330976 -1.5708 -0 -0.7854</pose>
        <inertial>
          <pose frame=''>0.026113 0.00159 -0.01117 0 -0 0</pose>
          <mass>2.07216</mass>
          <inertia>
            <ixx>0.00711585</ixx>
            <ixy>0.000360372</ixy>
            <ixz>0.00074588</ixz>
            <iyy>0.0131827</iyy>
            <iyz>-0.000196632</iyz>
            <izz>0.00926891</izz>
          </inertia>
        </inertial>
        <collision name='right_lower_elbow_collision'>
          <pose frame=''>0 0 0 0 -0 0</pose>
          <geometry>
            <cylinder>
              <length>0.1</length>
              <radius>0.06</radius>
            </cylinder>
          </geometry>
          <max_contacts>10</max_contacts>
          <surface>
            <contact>
              <ode/>
            </contact>
            <bounce/>
            <friction>
              <torsional>
                <ode/>
              </torsional>
              <ode/>
            </friction>
          </surface>
        </collision>
        <collision name='right_lower_elbow_fixed_joint_lump__right_upper_forearm_visual_collision_1'>
          <pose frame=''>0.224 -0 0 1.5708 -0 1.5708</pose>
          <geometry>
            <cylinder>
              <length>0.272</length>
              <radius>0.06</radius>
            </cylinder>
          </geometry>
          <max_contacts>10</max_contacts>
          <surface>
            <contact>
              <ode/>
            </contact>
            <bounce/>
            <friction>
              <torsional>
                <ode/>
              </torsional>
              <ode/>
            </friction>
          </surface>
        </collision>
        <visual name='right_lower_elbow_visual'>
          <pose frame=''>0 0 0 0 -0 0</pose>
          <geometry>
            <mesh>
              <scale>1 1 1</scale>
              <uri>/home/michaelwan/rethink_ws/src/baxter_common/baxter_description/meshes/lower_elbow/E1.DAE</uri>
            </mesh>
          </geometry>
        </visual>
        <self_collide>0</self_collide>
        <kinematic>0</kinematic>
      </link>
      <joint name='right_e1' type='revolute'>
        <child>right_lower_elbow</child>
        <parent>right_upper_elbow</parent>
        <axis>
          <xyz>0.707108 0.707105 0</xyz>
          <limit>
            <lower>-0.05</lower>
            <upper>2.618</upper>
            <effort>50</effort>
            <velocity>1.5</velocity>
          </limit>
          <dynamics>
            <damping>0.7</damping>
            <friction>0</friction>
            <spring_reference>0</spring_reference>
            <spring_stiffness>0</spring_stiffness>
          </dynamics>
          <use_parent_model_frame>1</use_parent_model_frame>
        </axis>
        <physics>
          <ode>
            <implicit_spring_damper>1</implicit_spring_damper>
            <cfm_damping>1</cfm_damping>
            <limit>
              <cfm>0</cfm>
              <erp>0.2</erp>
            </limit>
          </ode>
        </physics>
      </joint>
      <link name='right_upper_forearm'>
        <pose frame=''>0.44375 -0.638751 0.330976 -2.35619 1.57079 3.14159</pose>
        <inertial>
          <pose frame=''>-0.001682 0.0046 0.139519 0 -0 0</pose>
          <mass>2.24675</mass>
          <inertia>
            <ixx>0.0166775</ixx>
            <ixy>0.000184012</ixy>
            <ixz>0.000186469</ixz>
            <iyy>0.0167549</iyy>
            <iyz>-0.000647332</iyz>
            <izz>0.00374662</izz>
          </inertia>
        </inertial>
        <collision name='right_upper_forearm_collision'>
          <pose frame=''>0 0 -0.044 0 -0 0</pose>
          <geometry>
            <cylinder>
              <length>0.088</length>
              <radius>0.06</radius>
            </cylinder>
          </geometry>
          <max_contacts>10</max_contacts>
          <surface>
            <contact>
              <ode/>
            </contact>
            <bounce/>
            <friction>
              <torsional>
                <ode/>
              </torsional>
              <ode/>
            </friction>
          </surface>
        </collision>
        <visual name='right_upper_forearm_visual'>
          <pose frame=''>0 0 0 0 -0 0</pose>
          <geometry>
            <mesh>
              <scale>1 1 1</scale>
              <uri>/home/michaelwan/rethink_ws/src/baxter_common/baxter_description/meshes/upper_forearm/W0.DAE</uri>
            </mesh>
          </geometry>
        </visual>
        <self_collide>0</self_collide>
        <kinematic>0</kinematic>
      </link>
      <joint name='right_w0' type='revolute'>
        <child>right_upper_forearm</child>
        <parent>right_lower_elbow</parent>
        <axis>
          <xyz>0.707105 -0.707108 0</xyz>
          <limit>
            <lower>-3.059</lower>
            <upper>3.059</upper>
            <effort>15</effort>
            <velocity>4</velocity>
          </limit>
          <dynamics>
            <damping>0.7</damping>
            <friction>0</friction>
            <spring_reference>0</spring_reference>
            <spring_stiffness>0</spring_stiffness>
          </dynamics>
          <use_parent_model_frame>1</use_parent_model_frame>
        </axis>
        <physics>
          <ode>
            <implicit_spring_damper>1</implicit_spring_damper>
            <cfm_damping>1</cfm_damping>
            <limit>
              <cfm>0</cfm>
              <erp>0.2</erp>
            </limit>
          </ode>
        </physics>
      </joint>
      <link name='right_lower_forearm'>
        <pose frame=''>0.635163 -0.830166 0.320976 -1.5708 -0 -0.7854</pose>
        <inertial>
          <pose frame=''>0.06041 0.00697 0.006 0 -0 0</pose>
          <mass>1.60979</mass>
          <inertia>
            <ixx>0.00387607</ixx>
            <ixy>-0.000443848</ixy>
            <ixz>-0.00021115</ixz>
            <iyy>0.00700538</iyy>
            <iyz>0.000153481</iyz>
            <izz>0.00552755</izz>
          </inertia>
        </inertial>
        <collision name='right_lower_forearm_collision'>
          <pose frame=''>0 0 0 0 -0 0</pose>
          <geometry>
            <cylinder>
              <length>0.1</length>
              <radius>0.06</radius>
            </cylinder>
          </geometry>
          <max_contacts>10</max_contacts>
          <surface>
            <contact>
              <ode/>
            </contact>
            <bounce/>
            <friction>
              <torsional>
                <ode/>
              </torsional>
              <ode/>
            </friction>
          </surface>
        </collision>
        <visual name='right_lower_forearm_visual'>
          <pose frame=''>0 0 0 0 -0 0</pose>
          <geometry>
            <mesh>
              <scale>1 1 1</scale>
              <uri>/home/michaelwan/rethink_ws/src/baxter_common/baxter_description/meshes/lower_forearm/W1.DAE</uri>
            </mesh>
          </geometry>
        </visual>
        <self_collide>0</self_collide>
        <kinematic>0</kinematic>
      </link>
      <joint name='right_w1' type='revolute'>
        <child>right_lower_forearm</child>
        <parent>right_upper_forearm</parent>
        <axis>
          <xyz>0.707108 0.707105 0</xyz>
          <limit>
            <lower>-1.5708</lower>
            <upper>2.094</upper>
            <effort>15</effort>
            <velocity>4</velocity>
          </limit>
          <dynamics>
            <damping>0.7</damping>
            <friction>0</friction>
            <spring_reference>0</spring_reference>
            <spring_stiffness>0</spring_stiffness>
          </dynamics>
          <use_parent_model_frame>1</use_parent_model_frame>
        </axis>
        <physics>
          <ode>
            <implicit_spring_damper>1</implicit_spring_damper>
            <cfm_damping>1</cfm_damping>
            <limit>
              <cfm>0</cfm>
              <erp>0.2</erp>
            </limit>
          </ode>
        </physics>
      </joint>
      <link name='right_wrist'>
        <pose frame=''>0.71717 -0.912173 0.320976 -2.35619 1.57079 3.14159</pose>
        <inertial>
          <pose frame=''>0.003318 0.000616 0.079431 0 -0 0</pose>
          <mass>0.84268</mass>
          <inertia>
            <ixx>0.00284929</ixx>
            <ixy>7.17373e-06</ixy>
            <ixz>2.51907e-05</ixz>
            <iyy>0.00291605</iyy>
            <iyz>2.1733e-05</iyz>
            <izz>0.000560608</izz>
          </inertia>
        </inertial>
        <collision name='right_wrist_collision'>
          <pose frame=''>0 0 0 0 -0 0</pose>
          <geometry>
            <cylinder>
              <length>0.165</length>
              <radius>0.06</radius>
            </cylinder>
          </geometry>
          <max_contacts>10</max_contacts>
          <surface>
            <contact>
              <ode/>
            </contact>
            <bounce/>
            <friction>
              <torsional>
                <ode/>
              </torsional>
              <ode/>
            </friction>
          </surface>
        </collision>
        <collision name='right_wrist_fixed_joint_lump__right_hand_collision_1'>
          <pose frame=''>0 0 0.09035 0 -0 0</pose>
          <geometry>
            <cylinder>
              <length>0.0464</length>
              <radius>0.04</radius>
            </cylinder>
          </geometry>
          <max_contacts>10</max_contacts>
          <surface>
            <contact>
              <ode/>
            </contact>
            <bounce/>
            <friction>
              <torsional>
                <ode/>
              </torsional>
              <ode/>
            </friction>
          </surface>
        </collision>
        <collision name='right_wrist_fixed_joint_lump__right_gripper_base_collision_2'>
          <pose frame=''>0 0 0.13855 1.5708 -0 3.14159</pose>
          <geometry>
            <cylinder>
              <length>0.1</length>
              <radius>0.029</radius>
            </cylinder>
          </geometry>
          <max_contacts>10</max_contacts>
          <surface>
            <contact>
              <ode/>
            </contact>
            <bounce/>
            <friction>
              <torsional>
                <ode/>
              </torsional>
              <ode/>
            </friction>
          </surface>
        </collision>
        <visual name='right_wrist_visual'>
          <pose frame=''>0 0 0 0 -0 0</pose>
          <geometry>
            <mesh>
              <scale>1 1 1</scale>
              <uri>/home/michaelwan/rethink_ws/src/baxter_common/baxter_description/meshes/wrist/W2.DAE</uri>
            </mesh>
          </geometry>
        </visual>
        <visual name='right_wrist_fixed_joint_lump__right_gripper_base_visual_1'>
          <pose frame=''>0 0 0.13855 1.5708 -0 3.14159</pose>
          <geometry>
            <mesh>
              <scale>1 1 1</scale>
              <uri>/home/michaelwan/rethink_ws/src/baxter_common/rethink_ee_description/meshes/electric_gripper/electric_gripper_base.DAE</uri>
            </mesh>
          </geometry>
        </visual>
        <visual name='right_wrist_fixed_joint_lump__right_hand_accelerometer_visual_2'>
          <pose frame=''>0.00198 0.000133 0.09895 0 -0 0</pose>
          <geometry>
            <box>
              <size>0.01 0.01 0.01</size>
            </box>
          </geometry>
        </visual>
        <visual name='right_wrist_fixed_joint_lump__right_hand_camera_visual_3'>
          <pose frame=''>0.03825 0.012 0.128905 0 0 -1.5708</pose>
          <geometry>
            <cylinder>
              <length>0.01</length>
              <radius>0.02</radius>
            </cylinder>
          </geometry>
          <material>
            <script>
              <uri>__default__</uri>
              <name>__default__</name>
            </script>
          </material>
        </visual>
        <visual name='right_wrist_fixed_joint_lump__right_hand_range_visual_4'>
          <pose frame=''>0.032 -0.020245 0.14235 -3.14158 -1.57079 1.57078</pose>
          <geometry>
            <box>
              <size>0.005 0.02 0.005</size>
            </box>
          </geometry>
          <material>
            <script>
              <uri>__default__</uri>
              <name>__default__</name>
            </script>
          </material>
        </visual>
        <velocity_decay/>
        <sensor name='right_hand_camera' type='camera'>
          <update_rate>30</update_rate>
          <camera name='right_hand_camera'>
            <pose frame=''>0 0 0 -1.57079 -1.57079 3.14159</pose>
            <horizontal_fov>1.39626</horizontal_fov>
            <image>
              <width>800</width>
              <height>800</height>
              <format>R8G8B8</format>
            </image>
            <clip>
              <near>0.02</near>
              <far>300</far>
            </clip>
            <noise>
              <type>gaussian</type>
              <mean>0</mean>
              <stddev>0.007</stddev>
            </noise>
          </camera>
          <plugin name='camera_controller' filename='libgazebo_ros_camera.so'>
            <alwaysOn>true</alwaysOn>
            <updateRate>0.0</updateRate>
            <cameraName>right_hand_camera</cameraName>
            <imageTopicName>image</imageTopicName>
            <cameraInfoTopicName>camera_info</cameraInfoTopicName>
            <frameName>right_hand_camera</frameName>
            <hackBaseline>0.07</hackBaseline>
            <distortionK1>0.0</distortionK1>
            <distortionK2>0.0</distortionK2>
            <distortionK3>0.0</distortionK3>
            <distortionT1>0.0</distortionT1>
            <distortionT2>0.0</distortionT2>
            <CxPrime>0</CxPrime>
            <Cx>0.0</Cx>
            <Cy>0.0</Cy>
            <focalLength>0.0</focalLength>
            <robotNamespace>/cameras</robotNamespace>
          </plugin>
          <pose frame=''>0.03825 0.012 0.128905 0 0 -1.5708</pose>
        </sensor>
        <gravity>0</gravity>
        <velocity_decay/>
        <sensor name='ir_right' type='ray'>
          <ray>
            <scan>
              <horizontal>
                <samples>1</samples>
                <resolution>1</resolution>
                <min_angle>-0.5</min_angle>
                <max_angle>0.5</max_angle>
              </horizontal>
              <vertical>
                <samples>1</samples>
                <min_angle>0</min_angle>
                <max_angle>0</max_angle>
              </vertical>
            </scan>
            <range>
              <min>0.004</min>
              <max>0.4</max>
            </range>
          </ray>
          <plugin name='plugin_3' filename='libgazebo_ros_laser.so'>
            <gaussianNoise>0.005</gaussianNoise>
            <alwaysOn>true</alwaysOn>
            <updateRate>100</updateRate>
            <topicName>/sim/laserscan/right_hand_range/state</topicName>
            <frameName>right_hand_range</frameName>
            <robotNamespace>/</robotNamespace>
          </plugin>
          <always_on>1</always_on>
          <update_rate>100</update_rate>
          <pose frame=''>0.032 -0.020245 0.14235 -3.14158 -1.57079 1.57078</pose>
        </sensor>
        <self_collide>0</self_collide>
        <kinematic>0</kinematic>
      </link>
      <joint name='right_w2' type='revolute'>
        <child>right_wrist</child>
        <parent>right_lower_forearm</parent>
        <axis>
          <xyz>0.707105 -0.707108 0</xyz>
          <limit>
            <lower>-3.059</lower>
            <upper>3.059</upper>
            <effort>15</effort>
            <velocity>4</velocity>
          </limit>
          <dynamics>
            <damping>0.7</damping>
            <friction>0</friction>
            <spring_reference>0</spring_reference>
            <spring_stiffness>0</spring_stiffness>
          </dynamics>
          <use_parent_model_frame>1</use_parent_model_frame>
        </axis>
        <physics>
          <ode>
            <implicit_spring_damper>1</implicit_spring_damper>
            <cfm_damping>1</cfm_damping>
            <limit>
              <cfm>0</cfm>
              <erp>0.2</erp>
            </limit>
          </ode>
        </physics>
      </joint>
      <link name='r_gripper_l_finger'>
        <pose frame=''>0.821503 -1.03206 0.320976 -2.35619 1.57079 3.14159</pose>
        <inertial>
          <pose frame=''>0 0.00575 0.025 0 -0 3.14159</pose>
          <mass>0.03</mass>
          <inertia>
            <ixx>0.0200395</ixx>
            <ixy>4.0989e-19</ixy>
            <ixz>-1.78213e-18</ixz>
            <iyy>0.0200375</iyy>
            <iyz>8.625e-06</iyz>
            <izz>0.020002</izz>
          </inertia>
        </inertial>
        <collision name='r_gripper_l_finger_collision'>
          <pose frame=''>0 0.01725 0.04 0 -0 3.14159</pose>
          <geometry>
            <box>
              <size>0.01 0.0135 0.075</size>
            </box>
          </geometry>
          <surface>
            <contact>
              <ode>
                <kp>100000</kp>
                <kd>1</kd>
              </ode>
            </contact>
            <friction>
              <ode>
                <mu>1000</mu>
                <mu2>1000</mu2>
                <fdir1>0 0 1</fdir1>
              </ode>
              <torsional>
                <ode/>
              </torsional>
            </friction>
            <bounce/>
          </surface>
          <max_contacts>10</max_contacts>
        </collision>
        <collision name='r_gripper_l_finger_collision_1'>
          <pose frame=''>-0.005 -0.003 0.0083 0 -0 3.14159</pose>
          <geometry>
            <box>
              <size>0.01 0.05 0.017</size>
            </box>
          </geometry>
          <surface>
            <contact>
              <ode>
                <kp>100000</kp>
                <kd>1</kd>
              </ode>
            </contact>
            <friction>
              <ode>
                <mu>1000</mu>
                <mu2>1000</mu2>
                <fdir1>0 0 1</fdir1>
              </ode>
              <torsional>
                <ode/>
              </torsional>
            </friction>
            <bounce/>
          </surface>
          <max_contacts>10</max_contacts>
        </collision>
        <collision name='r_gripper_l_finger_tip_collision_2'>
          <pose frame=''>0 0.01275 0.06 0 -0 -3.14159</pose>
          <geometry>
            <box>
              <size>0.016 0.0065 0.037</size>
            </box>
          </geometry>
          <surface>
            <contact>
              <ode>
                <kp>100000</kp>
                <kd>1</kd>
              </ode>
            </contact>
            <friction>
              <ode>
                <mu>1000</mu>
                <mu2>1000</mu2>
                <fdir1>0 0 1</fdir1>
              </ode>
              <torsional>
                <ode/>
              </torsional>
            </friction>
            <bounce/>
          </surface>
          <max_contacts>10</max_contacts>
        </collision>
        <visual name='r_gripper_l_finger_visual'>
          <pose frame=''>0 0 0 0 -0 3.14159</pose>
          <geometry>
            <mesh>
              <scale>1 1 1</scale>
              <uri>/home/michaelwan/rethink_ws/src/baxter_common/rethink_ee_description/meshes/electric_gripper/fingers/standard_narrow.DAE</uri>
            </mesh>
          </geometry>
          <material>
            <script>
              <uri>__default__</uri>
              <name>__default__</name>
            </script>
          </material>
        </visual>
        <visual name='r_gripper_l_finger_tip_visual_1'>
          <pose frame=''>0 0.01725 0.075 0 -0 -3.14159</pose>
          <geometry>
            <mesh>
              <scale>1 1 1</scale>
              <uri>/home/michaelwan/rethink_ws/src/baxter_common/rethink_ee_description/meshes/electric_gripper/fingers/basic_hard_tip.DAE</uri>
            </mesh>
          </geometry>
          <material>
            <script>
              <uri>__default__</uri>
              <name>__default__</name>
            </script>
          </material>
        </visual>
        <gravity>1</gravity>
        <velocity_decay/>
        <self_collide>0</self_collide>
        <kinematic>0</kinematic>
      </link>
      <joint name='r_gripper_l_finger_joint' type='prismatic'>
        <child>r_gripper_l_finger</child>
        <parent>right_wrist</parent>
        <axis>
          <xyz>0.707108 0.707105 0</xyz>
          <limit>
            <lower>0</lower>
            <upper>0.020833</upper>
            <effort>20</effort>
            <velocity>5</velocity>
          </limit>
          <dynamics>
            <damping>0.7</damping>
            <friction>0</friction>
            <spring_reference>0</spring_reference>
            <spring_stiffness>0</spring_stiffness>
          </dynamics>
          <use_parent_model_frame>1</use_parent_model_frame>
        </axis>
        <physics>
          <ode>
            <implicit_spring_damper>1</implicit_spring_damper>
            <cfm_damping>1</cfm_damping>
            <limit>
              <cfm>0</cfm>
              <erp>0.2</erp>
            </limit>
          </ode>
        </physics>
      </joint>
      <link name='r_gripper_r_finger'>
        <pose frame=''>0.83706 -1.01651 0.320976 -2.35619 1.57079 3.14159</pose>
        <inertial>
          <pose frame=''>0 -0.00575 0.025 0 -0 0</pose>
          <mass>0.03</mass>
          <inertia>
            <ixx>0.0200395</ixx>
            <ixy>0</ixy>
            <ixz>0</ixz>
            <iyy>0.0200375</iyy>
            <iyz>8.625e-06</iyz>
            <izz>0.020002</izz>
          </inertia>
        </inertial>
        <collision name='r_gripper_r_finger_collision'>
          <pose frame=''>0 -0.01725 0.04 0 -0 0</pose>
          <geometry>
            <box>
              <size>0.01 0.0135 0.075</size>
            </box>
          </geometry>
          <surface>
            <contact>
              <ode>
                <kp>100000</kp>
                <kd>1</kd>
              </ode>
            </contact>
            <friction>
              <ode>
                <mu>1000</mu>
                <mu2>1000</mu2>
                <fdir1>0 0 1</fdir1>
              </ode>
              <torsional>
                <ode/>
              </torsional>
            </friction>
            <bounce/>
          </surface>
          <max_contacts>10</max_contacts>
        </collision>
        <collision name='r_gripper_r_finger_collision_1'>
          <pose frame=''>0.005 0.003 0.0083 0 -0 0</pose>
          <geometry>
            <box>
              <size>0.01 0.05 0.017</size>
            </box>
          </geometry>
          <surface>
            <contact>
              <ode>
                <kp>100000</kp>
                <kd>1</kd>
              </ode>
            </contact>
            <friction>
              <ode>
                <mu>1000</mu>
                <mu2>1000</mu2>
                <fdir1>0 0 1</fdir1>
              </ode>
              <torsional>
                <ode/>
              </torsional>
            </friction>
            <bounce/>
          </surface>
          <max_contacts>10</max_contacts>
        </collision>
        <collision name='r_gripper_r_finger_tip_collision_2'>
          <pose frame=''>0 -0.01275 0.06 0 -0 0</pose>
          <geometry>
            <box>
              <size>0.016 0.0065 0.037</size>
            </box>
          </geometry>
          <surface>
            <contact>
              <ode>
                <kp>100000</kp>
                <kd>1</kd>
              </ode>
            </contact>
            <friction>
              <ode>
                <mu>1000</mu>
                <mu2>1000</mu2>
                <fdir1>0 0 1</fdir1>
              </ode>
              <torsional>
                <ode/>
              </torsional>
            </friction>
            <bounce/>
          </surface>
          <max_contacts>10</max_contacts>
        </collision>
        <visual name='r_gripper_r_finger_visual'>
          <pose frame=''>0 0 0 0 -0 0</pose>
          <geometry>
            <mesh>
              <scale>1 1 1</scale>
              <uri>/home/michaelwan/rethink_ws/src/baxter_common/rethink_ee_description/meshes/electric_gripper/fingers/standard_narrow.DAE</uri>
            </mesh>
          </geometry>
          <material>
            <script>
              <uri>__default__</uri>
              <name>__default__</name>
            </script>
          </material>
        </visual>
        <visual name='r_gripper_r_finger_tip_visual_1'>
          <pose frame=''>0 -0.01725 0.075 0 -0 0</pose>
          <geometry>
            <mesh>
              <scale>1 1 1</scale>
              <uri>/home/michaelwan/rethink_ws/src/baxter_common/rethink_ee_description/meshes/electric_gripper/fingers/basic_hard_tip.DAE</uri>
            </mesh>
          </geometry>
          <material>
            <script>
              <uri>__default__</uri>
              <name>__default__</name>
            </script>
          </material>
        </visual>
        <gravity>1</gravity>
        <velocity_decay/>
        <self_collide>0</self_collide>
        <kinematic>0</kinematic>
      </link>
      <joint name='r_gripper_r_finger_joint' type='prismatic'>
        <child>r_gripper_r_finger</child>
        <parent>right_wrist</parent>
        <axis>
          <xyz>0.707108 0.707105 0</xyz>
          <limit>
            <lower>-0.020833</lower>
            <upper>0</upper>
            <effort>20</effort>
            <velocity>5</velocity>
          </limit>
          <dynamics>
            <damping>0.7</damping>
            <friction>0</friction>
            <spring_reference>0</spring_reference>
            <spring_stiffness>0</spring_stiffness>
          </dynamics>
          <use_parent_model_frame>1</use_parent_model_frame>
        </axis>
        <physics>
          <ode>
            <implicit_spring_damper>1</implicit_spring_damper>
            <cfm_damping>1</cfm_damping>
            <limit>
              <cfm>0</cfm>
              <erp>0.2</erp>
            </limit>
          </ode>
        </physics>
      </joint>
      <static>0</static>
      <plugin name='baxter_ros_control' filename='libbaxter_gazebo_ros_control.so'>
        <robotNamespace>/robot</robotNamespace>
        <robotSimType>gazebo_ros_control/DefaultRobotHWSim</robotSimType>
        <controlPeriod>0.001</controlPeriod>
      </plugin>
      <pose frame=''>0 0 0.93 0 -0 0</pose>
    </model>
    <state world_name='default'>
      <sim_time>298 190000000</sim_time>
      <real_time>139 115130624</real_time>
      <wall_time>1607130534 459053352</wall_time>
      <iterations>30414</iterations>
      <model name='baxter'>
        <pose frame=''>0 0 0.93 0 -0 0</pose>
        <scale>1 1 1</scale>
        <link name='base'>
          <pose frame=''>0 0 0.93 0 -0 0</pose>
          <velocity>0 0 0 0 -0 0</velocity>
          <acceleration>0 0 0 0 -0 0</acceleration>
          <wrench>0 0 0 0 -0 0</wrench>
        </link>
        <link name='head'>
          <pose frame=''>0.06 0 1.616 0 -0 0</pose>
          <velocity>0 0 0 0 -0 0</velocity>
          <acceleration>0 0 0 0 -0 0</acceleration>
          <wrench>0 0 0 0 -0 0</wrench>
        </link>
        <link name='l_gripper_l_finger'>
          <pose frame=''>0.177192 0.436398 0.33194 -3.13773 0.0843 -1.97187</pose>
          <velocity>1e-06 4.6e-05 4e-06 0.000167 -7.3e-05 4.9e-05</velocity>
          <acceleration>0 -1e-06 0 -2e-06 1e-06 -0</acceleration>
          <wrench>0 0 0 0 -0 0</wrench>
        </link>
        <link name='l_gripper_r_finger'>
          <pose frame=''>0.179124 0.435578 0.331942 -3.13773 0.0843 -1.97187</pose>
          <velocity>1.6e-05 3.9e-05 4e-06 0.000167 -7.3e-05 4.9e-05</velocity>
          <acceleration>0 -1e-06 0 -2e-06 1e-06 -0</acceleration>
          <wrench>0 0 0 0 -0 0</wrench>
        </link>
        <link name='left_lower_elbow'>
          <pose frame=''>0.171017 0.417881 0.979904 -1.55431 1.5536 0.993863</pose>
          <velocity>0 0 0 -1.7e-05 9e-06 4e-06</velocity>
          <acceleration>0 0 0 0 -0 0</acceleration>
          <wrench>0 0 0 0 -0 0</wrench>
        </link>
        <link name='left_lower_forearm'>
          <pose frame=''>0.170507 0.414123 0.605499 -1.60394 1.4864 1.12391</pose>
          <velocity>-3e-06 -7e-06 0 0.000167 -7.3e-05 4.7e-05</velocity>
          <acceleration>0 0 0 -2e-06 1e-06 -0</acceleration>
          <wrench>0 0 0 0 -0 0</wrench>
        </link>
        <link name='left_lower_shoulder'>
          <pose frame=''>0.102584 0.31625 1.32998 -1.5708 1.047 0.977869</pose>
          <velocity>0 0 0 0 -0 0</velocity>
          <acceleration>0 0 0 0 -0 0</acceleration>
          <wrench>0 0 0 0 -0 0</wrench>
        </link>
        <link name='left_upper_elbow'>
          <pose frame=''>0.131092 0.358559 1.24165 3.14126 0.523792 -2.16438</pose>
          <velocity>0 0 0 -1e-06 -2e-06 4e-06</velocity>
          <acceleration>0 0 0 0 -0 0</acceleration>
          <wrench>0 0 0 0 -0 0</wrench>
        </link>
        <link name='left_upper_forearm'>
          <pose frame=''>0.171989 0.419375 0.876329 -3.1388 0.016968 -1.98462</pose>
          <velocity>-1e-06 -2e-06 0 -1.8e-05 8e-06 4.6e-05</velocity>
          <acceleration>0 0 0 0 -0 0</acceleration>
          <wrench>0 0 0 0 -0 0</wrench>
        </link>
        <link name='left_upper_shoulder'>
          <pose frame=''>0.064027 0.259027 1.05963 0 -0 0.977869</pose>
          <velocity>0 0 0 0 -0 0</velocity>
          <acceleration>0 0 0 0 -0 0</acceleration>
          <wrench>0 0 0 0 -0 0</wrench>
        </link>
        <link name='left_wrist'>
          <pose frame=''>0.174732 0.422938 0.489937 -3.13773 0.0843 -1.97187</pose>
          <velocity>5e-06 1.3e-05 2e-06 0.000167 -7.3e-05 4.9e-05</velocity>
          <acceleration>0 0 0 -2e-06 1e-06 -0</acceleration>
          <wrench>0 0 0 0 -0 0</wrench>
        </link>
        <link name='r_gripper_l_finger'>
          <pose frame=''>0.15872 -0.448081 0.331955 3.14121 0.084462 2.14007</pose>
          <velocity>2.5e-05 -3.7e-05 4e-06 -0.000157 -0.000108 4.1e-05</velocity>
          <acceleration>0 0 0 2e-06 2e-06 0</acceleration>
          <wrench>0 0 0 0 -0 0</wrench>
        </link>
        <link name='r_gripper_r_finger'>
          <pose frame=''>0.176842 -0.436483 0.331958 3.14121 0.084462 2.14007</pose>
          <velocity>2.5e-05 -3.7e-05 5e-06 -0.000157 -0.000108 4.1e-05</velocity>
          <acceleration>0 0 0 2e-06 2e-06 0</acceleration>
          <wrench>0 0 0 0 -0 0</wrench>
        </link>
        <link name='right_lower_elbow'>
          <pose frame=''>0.157913 -0.425961 0.979904 -1.60643 1.55496 -1.09271</pose>
          <velocity>0 0 0 1.7e-05 1e-05 0</velocity>
          <acceleration>0 0 0 0 -0 0</acceleration>
          <wrench>0 0 0 0 -0 0</wrench>
        </link>
        <link name='right_lower_forearm'>
          <pose frame=''>0.155028 -0.422946 0.605503 -1.59284 1.48633 -0.996955</pose>
          <velocity>-4e-06 6e-06 0 -0.000157 -0.000108 4.1e-05</velocity>
          <acceleration>0 0 0 1e-06 2e-06 0</acceleration>
          <wrench>0 0 0 0 -0 0</wrench>
        </link>
        <link name='right_lower_shoulder'>
          <pose frame=''>0.097876 -0.319155 1.32998 -1.5708 1.047 -1.05806</pose>
          <velocity>0 0 0 0 -0 0</velocity>
          <acceleration>0 0 0 0 -0 0</acceleration>
          <wrench>0 0 0 0 -0 0</wrench>
        </link>
        <link name='right_upper_elbow'>
          <pose frame=''>0.122903 -0.363612 1.24165 -3.14093 0.523791 2.08484</pose>
          <velocity>0 0 0 0 -0 0</velocity>
          <acceleration>0 0 0 0 -0 0</acceleration>
          <wrench>0 0 0 0 -0 0</wrench>
        </link>
        <link name='right_upper_forearm'>
          <pose frame=''>0.158668 -0.427416 0.876327 -3.13973 0.015717 2.16663</pose>
          <velocity>-1e-06 2e-06 0 1.7e-05 1e-05 4.1e-05</velocity>
          <acceleration>0 0 0 -1e-06 0 0</acceleration>
          <wrench>0 0 0 0 -0 0</wrench>
        </link>
        <link name='right_upper_shoulder'>
          <pose frame=''>0.064027 -0.259027 1.05963 0 0 -1.05806</pose>
          <velocity>0 0 0 0 -0 0</velocity>
          <acceleration>0 0 0 0 -0 0</acceleration>
          <wrench>0 0 0 0 -0 0</wrench>
        </link>
        <link name='right_wrist'>
          <pose frame=''>0.160339 -0.431163 0.489941 3.14121 0.084462 2.14007</pose>
          <velocity>9e-06 -1.2e-05 2e-06 -0.000157 -0.000108 4.1e-05</velocity>
          <acceleration>0 0 0 2e-06 2e-06 0</acceleration>
          <wrench>0 0 0 0 -0 0</wrench>
        </link>
      </model>
      <model name='bouncy_ball_final'>
        <pose frame=''>1 0 0.05 0 -0 0</pose>
        <scale>1 1 1</scale>
        <link name='link_3'>
          <pose frame=''>1 0 0.05 0 -0 0</pose>
          <velocity>0 0 0 0 -0 0</velocity>
          <acceleration>0 0 0 0 -0 0</acceleration>
          <wrench>0 0 0 0 -0 0</wrench>
        </link>
      </model>
      <model name='ground_plane'>
        <pose frame=''>0 0 0 0 -0 0</pose>
        <scale>1 1 1</scale>
        <link name='link'>
          <pose frame=''>0 0 0 0 -0 0</pose>
          <velocity>0 0 0 0 -0 0</velocity>
          <acceleration>0 0 0 0 -0 0</acceleration>
          <wrench>0 0 0 0 -0 0</wrench>
        </link>
      </model>
      <model name='kinect_ros_1_nc'>
        <pose frame=''>0.1 0 0.95 0 -0.3 0</pose>
        <scale>1 1 1</scale>
        <link name='link'>
          <pose frame=''>0.1 0 0.95 0 -0.3 0</pose>
          <velocity>0 0 0 0 -0 0</velocity>
          <acceleration>0 0 0 0 -0 0</acceleration>
          <wrench>0 0 0 0 -0 0</wrench>
        </link>
      </model>
      <model name='kinect_ros_2_nc'>
        <pose frame=''>0.8 -1.3 0.95 -0 -0.3 1.3</pose>
        <scale>1 1 1</scale>
        <link name='link'>
          <pose frame=''>0.8 -1.3 0.95 -0 -0.3 1.3</pose>
          <velocity>0 0 0 0 -0 0</velocity>
          <acceleration>0 0 0 0 -0 0</acceleration>
          <wrench>0 0 0 0 -0 0</wrench>
        </link>
      </model>
      <model name='wooden_board__handle_final'>
        <pose frame=''>1.3 0 0.922 0 -0 0</pose>
        <scale>1 1 1</scale>
        <link name='link_0'>
          <pose frame=''>1.3 0 0.922 0 -0 0</pose>
          <velocity>0 0 0 0 -0 0</velocity>
          <acceleration>0 0 0 0 -0 0</acceleration>
          <wrench>0 0 0 0 -0 0</wrench>
        </link>
        <link name='link_2'>
          <pose frame=''>0.85 -0.3 0.922 0 -0 0</pose>
          <velocity>0 0 0 0 -0 0</velocity>
          <acceleration>0 0 0 0 -0 0</acceleration>
          <wrench>0 0 0 0 -0 0</wrench>
        </link>
        <link name='link_2_clone'>
          <pose frame=''>0.85 0.3 0.922 0 -0 0</pose>
          <velocity>0 0 0 0 -0 0</velocity>
          <acceleration>0 0 0 0 -0 0</acceleration>
          <wrench>0 0 0 0 -0 0</wrench>
        </link>
      </model>
      <light name='sun'>
        <pose frame=''>0 0 10 0 -0 0</pose>
      </light>
    </state>
    <model name='bouncy_ball_final'>
      <link name='link_3'>
        <pose frame=''>0 0 0 0 -0 0</pose>
        <inertial>
          <mass>0.01</mass>
          <inertia>
            <ixx>0.1</ixx>
            <ixy>0</ixy>
            <ixz>0</ixz>
            <iyy>0.1</iyy>
            <iyz>0</iyz>
            <izz>0.1</izz>
          </inertia>
          <pose frame=''>0 0 0 0 -0 0</pose>
        </inertial>
        <gravity>1</gravity>
        <self_collide>0</self_collide>
        <kinematic>0</kinematic>
        <visual name='visual'>
          <pose frame=''>0 0 0 0 -0 0</pose>
          <geometry>
            <sphere>
              <radius>0.05</radius>
            </sphere>
          </geometry>
          <material>
            <lighting>1</lighting>
            <script>
              <uri>file://media/materials/scripts/gazebo.material</uri>
              <name>Gazebo/Green</name>
            </script>
            <shader type='pixel'>
              <normal_map>__default__</normal_map>
            </shader>
            <ambient>0 1 0 1</ambient>
            <diffuse>0.7 0.7 0.7 1</diffuse>
            <specular>0.01 0.01 0.01 1</specular>
            <emissive>0 0 0 1</emissive>
          </material>
          <transparency>0</transparency>
          <cast_shadows>1</cast_shadows>
        </visual>
        <collision name='collision'>
          <laser_retro>0</laser_retro>
          <max_contacts>10</max_contacts>
          <pose frame=''>0 0 0 0 -0 0</pose>
          <geometry>
            <sphere>
              <radius>0.05</radius>
            </sphere>
          </geometry>
          <surface>
            <friction>
              <ode>
                <mu>1</mu>
                <mu2>1</mu2>
                <fdir1>0 0 0</fdir1>
                <slip1>0</slip1>
                <slip2>0</slip2>
              </ode>
              <torsional>
                <coefficient>1</coefficient>
                <patch_radius>0</patch_radius>
                <surface_radius>0</surface_radius>
                <use_patch_radius>1</use_patch_radius>
                <ode>
                  <slip>0</slip>
                </ode>
              </torsional>
            </friction>
            <bounce>
              <restitution_coefficient>1</restitution_coefficient>
              <threshold>0.01</threshold>
            </bounce>
            <contact>
              <collide_without_contact>0</collide_without_contact>
              <collide_without_contact_bitmask>1</collide_without_contact_bitmask>
              <collide_bitmask>1</collide_bitmask>
              <ode>
                <soft_cfm>0</soft_cfm>
                <soft_erp>0.2</soft_erp>
                <kp>1e+13</kp>
                <kd>1</kd>
                <max_vel>10</max_vel>
                <min_depth>0</min_depth>
              </ode>
              <bullet>
                <split_impulse>1</split_impulse>
                <split_impulse_penetration_threshold>-0.01</split_impulse_penetration_threshold>
                <soft_cfm>0</soft_cfm>
                <soft_erp>0.2</soft_erp>
                <kp>1e+13</kp>
                <kd>1</kd>
              </bullet>
            </contact>
          </surface>
        </collision>
      </link>
      <static>0</static>
      <allow_auto_disable>1</allow_auto_disable>
      <pose frame=''>1 0 2.5 0 -0 0</pose>
    </model>
    <model name='wooden_board__handle_final'>
      <link name='link_0'>
        <pose frame=''>0 0 0 0 -0 0</pose>
        <inertial>
          <mass>0.5</mass>
          <inertia>
            <ixx>0.010433</ixx>
            <ixy>0</ixy>
            <ixz>0</ixz>
            <iyy>0.005121</iyy>
            <iyz>0</iyz>
            <izz>0.01552</izz>
          </inertia>
          <pose frame=''>0 0 0 0 -0 0</pose>
        </inertial>
        <self_collide>0</self_collide>
        <kinematic>0</kinematic>
        <gravity>0</gravity>
        <visual name='visual'>
          <pose frame=''>0 0 0 0 -0 0</pose>
          <geometry>
            <box>
              <size>0.35 0.5 0.02</size>
            </box>
          </geometry>
          <material>
            <lighting>1</lighting>
            <script>
              <uri>file://media/materials/scripts/gazebo.material</uri>
              <name>Gazebo/Red</name>
            </script>
            <shader type='pixel'>
              <normal_map>__default__</normal_map>
            </shader>
            <ambient>1 0 0 1</ambient>
            <diffuse>0.7 0.7 0.7 1</diffuse>
            <specular>0.01 0.01 0.01 1</specular>
            <emissive>0 0 0 1</emissive>
          </material>
          <transparency>0</transparency>
          <cast_shadows>1</cast_shadows>
        </visual>
        <collision name='collision'>
          <laser_retro>0</laser_retro>
          <max_contacts>10</max_contacts>
          <pose frame=''>0 0 0 0 -0 0</pose>
          <geometry>
            <box>
              <size>0.35 0.5 0.02</size>
            </box>
          </geometry>
          <surface>
            <friction>
              <ode>
                <mu>0</mu>
                <mu2>0</mu2>
                <fdir1>0 0 0</fdir1>
                <slip1>0</slip1>
                <slip2>0</slip2>
              </ode>
              <torsional>
                <coefficient>1</coefficient>
                <patch_radius>0</patch_radius>
                <surface_radius>0</surface_radius>
                <use_patch_radius>1</use_patch_radius>
                <ode>
                  <slip>0</slip>
                </ode>
              </torsional>
            </friction>
            <bounce>
              <restitution_coefficient>1</restitution_coefficient>
              <threshold>0.01</threshold>
            </bounce>
            <contact>
              <collide_without_contact>0</collide_without_contact>
              <collide_without_contact_bitmask>1</collide_without_contact_bitmask>
              <collide_bitmask>1</collide_bitmask>
              <ode>
                <soft_cfm>0</soft_cfm>
                <soft_erp>0.2</soft_erp>
                <kp>1e+13</kp>
                <kd>1</kd>
                <max_vel>10</max_vel>
                <min_depth>0</min_depth>
              </ode>
              <bullet>
                <split_impulse>1</split_impulse>
                <split_impulse_penetration_threshold>-0.01</split_impulse_penetration_threshold>
                <soft_cfm>0</soft_cfm>
                <soft_erp>0.2</soft_erp>
                <kp>1e+13</kp>
                <kd>1</kd>
              </bullet>
            </contact>
          </surface>
        </collision>
      </link>
      <link name='link_2'>
        <pose frame=''>-0.45 -0.3 0 0 -0 0</pose>
        <inertial>
          <mass>0.001</mass>
          <inertia>
            <ixx>2.8e-07</ixx>
            <ixy>0</ixy>
            <ixz>0</ixz>
            <iyy>3.54e-06</iyy>
            <iyz>0</iyz>
            <izz>5.3e-07</izz>
          </inertia>
          <pose frame=''>0 0 0 0 -0 0</pose>
        </inertial>
        <self_collide>0</self_collide>
        <kinematic>0</kinematic>
        <gravity>0</gravity>
        <visual name='visual'>
          <pose frame=''>0 0 0 0 -0 0</pose>
          <geometry>
            <box>
              <size>0.2 0.03 0.05</size>
            </box>
          </geometry>
          <material>
            <lighting>1</lighting>
            <script>
              <uri>file://media/materials/scripts/gazebo.material</uri>
              <name>Gazebo/Purple</name>
            </script>
            <shader type='pixel'>
              <normal_map>__default__</normal_map>
            </shader>
            <ambient>1 0 1 1</ambient>
            <diffuse>0.7 0.7 0.7 1</diffuse>
            <specular>0.01 0.01 0.01 1</specular>
            <emissive>0 0 0 1</emissive>
          </material>
          <transparency>0</transparency>
          <cast_shadows>1</cast_shadows>
        </visual>
        <collision name='collision'>
          <laser_retro>0</laser_retro>
          <max_contacts>10</max_contacts>
          <pose frame=''>0 0 0 0 -0 0</pose>
          <geometry>
            <box>
              <size>0.2 0.03 0.05</size>
            </box>
          </geometry>
          <surface>
            <friction>
              <ode>
                <mu>1</mu>
                <mu2>1</mu2>
                <fdir1>0 0 0</fdir1>
                <slip1>0</slip1>
                <slip2>0</slip2>
              </ode>
              <torsional>
                <coefficient>1</coefficient>
                <patch_radius>0</patch_radius>
                <surface_radius>0</surface_radius>
                <use_patch_radius>1</use_patch_radius>
                <ode>
                  <slip>0</slip>
                </ode>
              </torsional>
            </friction>
            <bounce>
              <restitution_coefficient>0</restitution_coefficient>
              <threshold>1e+06</threshold>
            </bounce>
            <contact>
              <collide_without_contact>0</collide_without_contact>
              <collide_without_contact_bitmask>1</collide_without_contact_bitmask>
              <collide_bitmask>1</collide_bitmask>
              <ode>
                <soft_cfm>0</soft_cfm>
                <soft_erp>0.2</soft_erp>
                <kp>1e+13</kp>
                <kd>1</kd>
                <max_vel>0.01</max_vel>
                <min_depth>0</min_depth>
              </ode>
              <bullet>
                <split_impulse>1</split_impulse>
                <split_impulse_penetration_threshold>-0.01</split_impulse_penetration_threshold>
                <soft_cfm>0</soft_cfm>
                <soft_erp>0.2</soft_erp>
                <kp>1e+13</kp>
                <kd>1</kd>
              </bullet>
            </contact>
          </surface>
        </collision>
      </link>
      <link name='link_2_clone'>
        <pose frame=''>-0.45 0.3 0 0 -0 0</pose>
        <inertial>
          <mass>0.001</mass>
          <inertia>
            <ixx>2.8e-07</ixx>
            <ixy>0</ixy>
            <ixz>0</ixz>
            <iyy>5.34e-06</iyy>
            <iyz>0</iyz>
            <izz>5.3e-07</izz>
          </inertia>
          <pose frame=''>0 0 0 0 -0 0</pose>
        </inertial>
        <self_collide>0</self_collide>
        <kinematic>0</kinematic>
        <gravity>0</gravity>
        <visual name='visual'>
          <pose frame=''>0 0 0 0 -0 0</pose>
          <geometry>
            <box>
              <size>0.2 0.03 0.05</size>
            </box>
          </geometry>
          <material>
            <lighting>1</lighting>
            <script>
              <uri>file://media/materials/scripts/gazebo.material</uri>
              <name>Gazebo/Purple</name>
            </script>
            <shader type='pixel'>
              <normal_map>__default__</normal_map>
            </shader>
            <ambient>1 0 1 1</ambient>
            <diffuse>0.7 0.7 0.7 1</diffuse>
            <specular>0.01 0.01 0.01 1</specular>
            <emissive>0 0 0 1</emissive>
          </material>
          <transparency>0</transparency>
          <cast_shadows>1</cast_shadows>
        </visual>
        <collision name='collision'>
          <laser_retro>0</laser_retro>
          <max_contacts>10</max_contacts>
          <pose frame=''>0 0 0 0 -0 0</pose>
          <geometry>
            <box>
              <size>0.2 0.03 0.05</size>
            </box>
          </geometry>
          <surface>
            <friction>
              <ode>
                <mu>1</mu>
                <mu2>1</mu2>
                <fdir1>0 0 0</fdir1>
                <slip1>0</slip1>
                <slip2>0</slip2>
              </ode>
              <torsional>
                <coefficient>1</coefficient>
                <patch_radius>0</patch_radius>
                <surface_radius>0</surface_radius>
                <use_patch_radius>1</use_patch_radius>
                <ode>
                  <slip>0</slip>
                </ode>
              </torsional>
            </friction>
            <bounce>
              <restitution_coefficient>0</restitution_coefficient>
              <threshold>1e+06</threshold>
            </bounce>
            <contact>
              <collide_without_contact>0</collide_without_contact>
              <collide_without_contact_bitmask>1</collide_without_contact_bitmask>
              <collide_bitmask>1</collide_bitmask>
              <ode>
                <soft_cfm>0</soft_cfm>
                <soft_erp>0.2</soft_erp>
                <kp>1e+13</kp>
                <kd>1</kd>
                <max_vel>0.01</max_vel>
                <min_depth>0</min_depth>
              </ode>
              <bullet>
                <split_impulse>1</split_impulse>
                <split_impulse_penetration_threshold>-0.01</split_impulse_penetration_threshold>
                <soft_cfm>0</soft_cfm>
                <soft_erp>0.2</soft_erp>
                <kp>1e+13</kp>
                <kd>1</kd>
              </bullet>
            </contact>
          </surface>
        </collision>
      </link>
      <joint name='link_0_JOINT_0' type='revolute'>
        <parent>link_0</parent>
        <child>link_2</child>
        <pose frame=''>0 0 0 0 -0 0</pose>
        <axis>
          <xyz>1 0 0</xyz>
          <use_parent_model_frame>0</use_parent_model_frame>
          <limit>
            <lower>-0</lower>
            <upper>0</upper>
            <effort>0</effort>
            <velocity>0</velocity>
          </limit>
          <dynamics>
            <spring_reference>0</spring_reference>
            <spring_stiffness>0</spring_stiffness>
            <damping>0</damping>
            <friction>0</friction>
          </dynamics>
        </axis>
        <physics>
          <ode>
            <limit>
              <cfm>0</cfm>
              <erp>0.2</erp>
            </limit>
            <suspension>
              <cfm>0</cfm>
              <erp>0.2</erp>
            </suspension>
          </ode>
        </physics>
      </joint>
      <joint name='link_0_JOINT_1' type='revolute'>
        <parent>link_0</parent>
        <child>link_2_clone</child>
        <pose frame=''>0 0 0 0 -0 0</pose>
        <axis>
          <xyz>1 0 0</xyz>
          <use_parent_model_frame>0</use_parent_model_frame>
          <limit>
            <lower>-0</lower>
            <upper>0</upper>
            <effort>0</effort>
            <velocity>0</velocity>
          </limit>
          <dynamics>
            <spring_reference>0</spring_reference>
            <spring_stiffness>0</spring_stiffness>
            <damping>0</damping>
            <friction>0</friction>
          </dynamics>
        </axis>
        <physics>
          <ode>
            <limit>
              <cfm>0</cfm>
              <erp>0.2</erp>
            </limit>
            <suspension>
              <cfm>0</cfm>
              <erp>0.2</erp>
            </suspension>
          </ode>
        </physics>
      </joint>
      <static>0</static>
      <allow_auto_disable>1</allow_auto_disable>
      <pose frame=''>1.3 0 0.922 0 -0 0</pose>
    </model>
    <model name='kinect_ros_1_nc'>
      <link name='link'>
        <pose frame=''>0 0 0 0 -0 0</pose>
        <inertial>
          <mass>0.1</mass>
          <inertia>
            <ixx>1</ixx>
            <ixy>0</ixy>
            <ixz>0</ixz>
            <iyy>1</iyy>
            <iyz>0</iyz>
            <izz>1</izz>
          </inertia>
          <pose frame=''>0 0 0 0 -0 0</pose>
        </inertial>
        <self_collide>0</self_collide>
        <kinematic>0</kinematic>
        <sensor name='camera' type='depth'>
          <update_rate>20</update_rate>
          <camera name='__default__'>
            <horizontal_fov>1.0472</horizontal_fov>
            <image>
              <width>640</width>
              <height>480</height>
              <format>R8G8B8</format>
            </image>
            <clip>
              <near>0.05</near>
              <far>3</far>
            </clip>
          </camera>
          <plugin name='camera_plugin' filename='libgazebo_ros_openni_kinect.so'>
            <baseline>0.2</baseline>
            <alwaysOn>true</alwaysOn>
            <updateRate>0.0</updateRate>
            <cameraName>camera_ir</cameraName>
            <imageTopicName>/camera/kinect1/color/image_raw</imageTopicName>
            <cameraInfoTopicName>/camera/kinect1/color/camera_info</cameraInfoTopicName>
            <depthImageTopicName>/camera/kinect1/depth/image_raw</depthImageTopicName>
            <depthImageCameraInfoTopicName>/camera/kinect1/depth/camera_info</depthImageCameraInfoTopicName>
            <pointCloudTopicName>/camera/kinect1/depth/points</pointCloudTopicName>
            <frameName>world</frameName>
            <pointCloudCutoff>0.5</pointCloudCutoff>
            <pointCloudCutoffMax>3.0</pointCloudCutoffMax>
            <distortionK1>0</distortionK1>
            <distortionK2>0</distortionK2>
            <distortionK3>0</distortionK3>
            <distortionT1>0</distortionT1>
            <distortionT2>0</distortionT2>
            <CxPrime>0</CxPrime>
            <Cx>0</Cx>
            <Cy>0</Cy>
            <focalLength>0</focalLength>
            <hackBaseline>0</hackBaseline>
          </plugin>
        </sensor>
        <gravity>0</gravity>
        <visual name='visual'>
          <geometry>
            <mesh>
              <uri>/home/michaelwan/.gazebo/models/kinect_ros_1_nc/meshes/kinect.dae</uri>
            </mesh>
          </geometry>
          <material>
            <shader type='pixel'>
              <normal_map>__default__</normal_map>
            </shader>
          </material>
          <pose frame=''>0 0 0 0 -0 0</pose>
          <cast_shadows>1</cast_shadows>
          <transparency>0</transparency>
        </visual>
        <visual name='visual'>
          <geometry>
            <mesh>
              <uri>model://kinect_ros_1_nc/meshes/kinect.dae</uri>
            </mesh>
          </geometry>
          <material>
            <shader type='pixel'>
              <normal_map>__default__</normal_map>
            </shader>
          </material>
          <pose frame=''>0 0 0 0 -0 0</pose>
          <cast_shadows>1</cast_shadows>
          <transparency>0</transparency>
        </visual>
      </link>
      <static>0</static>
      <allow_auto_disable>1</allow_auto_disable>
      <pose frame=''>0.898926 1.5555 0 0 -0 0</pose>
    </model>
    <model name='kinect_ros_2_nc'>
      <link name='link'>
        <pose frame=''>0 0 0 0 -0 0</pose>
        <inertial>
          <mass>0.1</mass>
          <inertia>
            <ixx>1</ixx>
            <ixy>0</ixy>
            <ixz>0</ixz>
            <iyy>1</iyy>
            <iyz>0</iyz>
            <izz>1</izz>
          </inertia>
          <pose frame=''>0 0 0 0 -0 0</pose>
        </inertial>
        <self_collide>0</self_collide>
        <kinematic>0</kinematic>
        <sensor name='camera' type='depth'>
          <update_rate>20</update_rate>
          <camera name='__default__'>
            <horizontal_fov>1.0472</horizontal_fov>
            <image>
              <width>640</width>
              <height>480</height>
              <format>R8G8B8</format>
            </image>
            <clip>
              <near>0.05</near>
              <far>3</far>
            </clip>
          </camera>
          <plugin name='camera_plugin' filename='libgazebo_ros_openni_kinect.so'>
            <baseline>0.2</baseline>
            <alwaysOn>true</alwaysOn>
            <updateRate>0.0</updateRate>
            <cameraName>camera_ir</cameraName>
            <imageTopicName>/camera/kinect2/color/image_raw</imageTopicName>
            <cameraInfoTopicName>/camera/kinect2/color/camera_info</cameraInfoTopicName>
            <depthImageTopicName>/camera/kinect2/depth/image_raw</depthImageTopicName>
            <depthImageCameraInfoTopicName>/camera/kinect2/depth/camera_info</depthImageCameraInfoTopicName>
            <pointCloudTopicName>/camera/kinect2/depth/points</pointCloudTopicName>
            <frameName>world</frameName>
            <pointCloudCutoff>0.5</pointCloudCutoff>
            <pointCloudCutoffMax>3.0</pointCloudCutoffMax>
            <distortionK1>0</distortionK1>
            <distortionK2>0</distortionK2>
            <distortionK3>0</distortionK3>
            <distortionT1>0</distortionT1>
            <distortionT2>0</distortionT2>
            <CxPrime>0</CxPrime>
            <Cx>0</Cx>
            <Cy>0</Cy>
            <focalLength>0</focalLength>
            <hackBaseline>0</hackBaseline>
          </plugin>
        </sensor>
        <gravity>0</gravity>
        <visual name='visual'>
          <geometry>
            <mesh>
              <uri>/home/michaelwan/.gazebo/models/kinect_ros_2_nc/meshes/kinect.dae</uri>
            </mesh>
          </geometry>
          <material>
            <shader type='pixel'>
              <normal_map>__default__</normal_map>
            </shader>
          </material>
          <pose frame=''>0 0 0 0 -0 0</pose>
          <cast_shadows>1</cast_shadows>
          <transparency>0</transparency>
        </visual>
        <visual name='visual'>
          <geometry>
            <mesh>
              <uri>model://kinect_ros_2_nc/meshes/kinect.dae</uri>
            </mesh>
          </geometry>
          <material>
            <shader type='pixel'>
              <normal_map>__default__</normal_map>
            </shader>
          </material>
          <pose frame=''>0 0 0 0 -0 0</pose>
          <cast_shadows>1</cast_shadows>
          <transparency>0</transparency>
        </visual>
      </link>
      <static>0</static>
      <allow_auto_disable>1</allow_auto_disable>
      <pose frame=''>1.28798 -1.31935 0 0 -0 0</pose>
    </model>
  </world>
</sdf>
